Workbook

Sheet التكاليف
A1: التكاليف التشغيلية — مواد وأجور عمال
A2: الجهة | B2: محلات العون — مصاريف المحل
A4: البنود | B4: =COUNTA(E7:E806) | C4: المجموع | D4: =SUM(H7:H806) | E4: منها أصول | F4: =SUMIF(J7:J806,"أصل",H7:H806) | G4: المدقَّقة | H4: =SUMPRODUCT((E7:E806<>"")*(K7:K806<>"")) | I4: ناقص ⚠ | J4: =SUMPRODUCT((E7:E806<>"")*(LEFT(J7:J806,1)="⚠"))
A6: # | B6: التاريخ | C6: اليوم | D6: الورشة (شغل داخلي) | E6: البند | F6: الكمية | G6: الإفرادي | H6: الإجمالي | I6: الغرض | J6: أصل؟ | K6: المدقق | L6: ملاحظات إضافية
A7: =IF(E7="","",ROW()-6) | C7: =IF(B7="","",CHOOSE(WEEKDAY(B7,1),"الأحد","الاثنين","الثلاثاء","الأربعاء","الخميس","الجمعة","السبت")) | H7: =IF(OR(F7="",G7=""),"",ROUND(F7*G7,2)) | I7: =IF(ISNUMBER(SEARCH("ستاند",D7)),"أثاث وستاندات","") | J7: =IF(E7="","",IF(I7="","⚠ عبّي الغرض",IF(AND(D7<>"",OR(ISNUMBER(SEARCH("صيانة",D7)),ISNUMBER(SEARCH("تعزيل",D7)),ISNUMBER(SEARCH("تنظيف",D7)),ISNUMBER(SEARCH("تصليح",D7)))),"⚠ الصيانة بلا ورشة",IF(H7="","⚠ ناقص",IF(D7<>"",IF(SUMIF($D$7:$D$806,D7,$H$7:$H$806)>=20,"أصل","مصروف"),IFERROR(IF(VLOOKUP(I7,'القوائم'!$A$2:$D$14,4,0)="زكاة وصدقة","زكاة وصدقة",IF(AND(VLOOKUP(I7,'القوائم'!$A$2:$D$14,3,0)<>"",H7>=20),"أصل","مصروف")),"مصروف")))))) | N7: =IF(B7="","",MONTH(B7)) | O7: =IF(B7="","",YEAR(B7)) | P7: =IF(AND(D7<>"",COUNTIF(D$7:D7,D7)=1),MAX(P$6:P6)+1,"") | Q7: =IF(E7="","",IF(I7="أجور عمال","أجرة","مادة"))
A8: =IF(E8="","",ROW()-6) | C8: =IF(B8="","",CHOOSE(WEEKDAY(B8,1),"الأحد","الاثنين","الثلاثاء","الأربعاء","الخميس","الجمعة","السبت")) | H8: =IF(OR(F8="",G8=""),"",ROUND(F8*G8,2)) | I8: =IF(ISNUMBER(SEARCH("ستاند",D8)),"أثاث وستاندات","") | J8: =IF(E8="","",IF(I8="","⚠ عبّي الغرض",IF(AND(D8<>"",OR(ISNUMBER(SEARCH("صيانة",D8)),ISNUMBER(SEARCH("تعزيل",D8)),ISNUMBER(SEARCH("تنظيف",D8)),ISNUMBER(SEARCH("تصليح",D8)))),"⚠ الصيانة بلا ورشة",IF(H8="","⚠ ناقص",IF(D8<>"",IF(SUMIF($D$7:$D$806,D8,$H$7:$H$806)>=20,"أصل","مصروف"),IFERROR(IF(VLOOKUP(I8,'القوائم'!$A$2:$D$14,4,0)="زكاة وصدقة","زكاة وصدقة",IF(AND(VLOOKUP(I8,'القوائم'!$A$2:$D$14,3,0)<>"",H8>=20),"أصل","مصروف")),"مصروف")))))) | N8: =IF(B8="","",MONTH(B8)) | O8: =IF(B8="","",YEAR(B8)) | P8: =IF(AND(D8<>"",COUNTIF(D$7:D8,D8)=1),MAX(P$6:P7)+1,"") | Q8: =IF(E8="","",IF(I8="أجور عمال","أجرة","مادة"))
A9: =IF(E9="","",ROW()-6) | C9: =IF(B9="","",CHOOSE(WEEKDAY(B9,1),"الأحد","الاثنين","الثلاثاء","الأربعاء","الخميس","الجمعة","السبت")) | H9: =IF(OR(F9="",G9=""),"",ROUND(F9*G9,2)) | I9: =IF(ISNUMBER(SEARCH("ستاند",D9)),"أثاث وستاندات","") | J9: =IF(E9="","",IF(I9="","⚠ عبّي الغرض",IF(AND(D9<>"",OR(ISNUMBER(SEARCH("صيانة",D9)),ISNUMBER(SEARCH("تعزيل",D9)),ISNUMBER(SEARCH("تنظيف",D9)),ISNUMBER(SEARCH("تصليح",D9)))),"⚠ الصيانة بلا ورشة",IF(H9="","⚠ ناقص",IF(D9<>"",IF(SUMIF($D$7:$D$806,D9,$H$7:$H$806)>=20,"أصل","مصروف"),IFERROR(IF(VLOOKUP(I9,'القوائم'!$A$2:$D$14,4,0)="زكاة وصدقة","زكاة وصدقة",IF(AND(VLOOKUP(I9,'القوائم'!$A$2:$D$14,3,0)<>"",H9>=20),"أصل","مصروف")),"مصروف")))))) | N9: =IF(B9="","",MONTH(B9)) | O9: =IF(B9="","",YEAR(B9)) | P9: =IF(AND(D9<>"",COUNTIF(D$7:D9,D9)=1),MAX(P$6:P8)+1,"") | Q9: =IF(E9="","",IF(I9="أجور عمال","أجرة","مادة"))
A10: =IF(E10="","",ROW()-6) | C10: =IF(B10="","",CHOOSE(WEEKDAY(B10,1),"الأحد","الاثنين","الثلاثاء","الأربعاء","الخميس","الجمعة","السبت")) | H10: =IF(OR(F10="",G10=""),"",ROUND(F10*G10,2)) | I10: =IF(ISNUMBER(SEARCH("ستاند",D10)),"أثاث وستاندات","") | J10: =IF(E10="","",IF(I10="","⚠ عبّي الغرض",IF(AND(D10<>"",OR(ISNUMBER(SEARCH("صيانة",D10)),ISNUMBER(SEARCH("تعزيل",D10)),ISNUMBER(SEARCH("تنظيف",D10)),ISNUMBER(SEARCH("تصليح",D10)))),"⚠ الصيانة بلا ورشة",IF(H10="","⚠ ناقص",IF(D10<>"",IF(SUMIF($D$7:$D$806,D10,$H$7:$H$806)>=20,"أصل","مصروف"),IFERROR(IF(VLOOKUP(I10,'القوائم'!$A$2:$D$14,4,0)="زكاة وصدقة","زكاة وصدقة",IF(AND(VLOOKUP(I10,'القوائم'!$A$2:$D$14,3,0)<>"",H10>=20),"أصل","مصروف")),"مصروف")))))) | N10: =IF(B10="","",MONTH(B10)) | O10: =IF(B10="","",YEAR(B10)) | P10: =IF(AND(D10<>"",COUNTIF(D$7:D10,D10)=1),MAX(P$6:P9)+1,"") | Q10: =IF(E10="","",IF(I10="أجور عمال","أجرة","مادة"))
A11: =IF(E11="","",ROW()-6) | C11: =IF(B11="","",CHOOSE(WEEKDAY(B11,1),"الأحد","الاثنين","الثلاثاء","الأربعاء","الخميس","الجمعة","السبت")) | H11: =IF(OR(F11="",G11=""),"",ROUND(F11*G11,2)) | I11: =IF(ISNUMBER(SEARCH("ستاند",D11)),"أثاث وستاندات","") | J11: =IF(E11="","",IF(I11="","⚠ عبّي الغرض",IF(AND(D11<>"",OR(ISNUMBER(SEARCH("صيانة",D11)),ISNUMBER(SEARCH("تعزيل",D11)),ISNUMBER(SEARCH("تنظيف",D11)),ISNUMBER(SEARCH("تصليح",D11)))),"⚠ الصيانة بلا ورشة",IF(H11="","⚠ ناقص",IF(D11<>"",IF(SUMIF($D$7:$D$806,D11,$H$7:$H$806)>=20,"أصل","مصروف"),IFERROR(IF(VLOOKUP(I11,'القوائم'!$A$2:$D$14,4,0)="زكاة وصدقة","زكاة وصدقة",IF(AND(VLOOKUP(I11,'القوائم'!$A$2:$D$14,3,0)<>"",H11>=20),"أصل","مصروف")),"مصروف")))))) | N11: =IF(B11="","",MONTH(B11)) | O11: =IF(B11="","",YEAR(B11)) | P11: =IF(AND(D11<>"",COUNTIF(D$7:D11,D11)=1),MAX(P$6:P10)+1,"") | Q11: =IF(E11="","",IF(I11="أجور عمال","أجرة","مادة"))
A12: =IF(E12="","",ROW()-6) | C12: =IF(B12="","",CHOOSE(WEEKDAY(B12,1),"الأحد","الاثنين","الثلاثاء","الأربعاء","الخميس","الجمعة","السبت")) | H12: =IF(OR(F12="",G12=""),"",ROUND(F12*G12,2)) | I12: =IF(ISNUMBER(SEARCH("ستاند",D12)),"أثاث وستاندات","") | J12: =IF(E12="","",IF(I12="","⚠ عبّي الغرض",IF(AND(D12<>"",OR(ISNUMBER(SEARCH("صيانة",D12)),ISNUMBER(SEARCH("تعزيل",D12)),ISNUMBER(SEARCH("تنظيف",D12)),ISNUMBER(SEARCH("تصليح",D12)))),"⚠ الصيانة بلا ورشة",IF(H12="","⚠ ناقص",IF(D12<>"",IF(SUMIF($D$7:$D$806,D12,$H$7:$H$806)>=20,"أصل","مصروف"),IFERROR(IF(VLOOKUP(I12,'القوائم'!$A$2:$D$14,4,0)="زكاة وصدقة","زكاة وصدقة",IF(AND(VLOOKUP(I12,'القوائم'!$A$2:$D$14,3,0)<>"",H12>=20),"أصل","مصروف")),"مصروف")))))) | N12: =IF(B12="","",MONTH(B12)) | O12: =IF(B12="","",YEAR(B12)) | P12: =IF(AND(D12<>"",COUNTIF(D$7:D12,D12)=1),MAX(P$6:P11)+1,"") | Q12: =IF(E12="","",IF(I12="أجور عمال","أجرة","مادة"))
A13: =IF(E13="","",ROW()-6) | C13: =IF(B13="","",CHOOSE(WEEKDAY(B13,1),"الأحد","الاثنين","الثلاثاء","الأربعاء","الخميس","الجمعة","السبت")) | H13: =IF(OR(F13="",G13=""),"",ROUND(F13*G13,2)) | I13: =IF(ISNUMBER(SEARCH("ستاند",D13)),"أثاث وستاندات","") | J13: =IF(E13="","",IF(I13="","⚠ عبّي الغرض",IF(AND(D13<>"",OR(ISNUMBER(SEARCH("صيانة",D13)),ISNUMBER(SEARCH("تعزيل",D13)),ISNUMBER(SEARCH("تنظيف",D13)),ISNUMBER(SEARCH("تصليح",D13)))),"⚠ الصيانة بلا ورشة",IF(H13="","⚠ ناقص",IF(D13<>"",IF(SUMIF($D$7:$D$806,D13,$H$7:$H$806)>=20,"أصل","مصروف"),IFERROR(IF(VLOOKUP(I13,'القوائم'!$A$2:$D$14,4,0)="زكاة وصدقة","زكاة وصدقة",IF(AND(VLOOKUP(I13,'القوائم'!$A$2:$D$14,3,0)<>"",H13>=20),"أصل","مصروف")),"مصروف")))))) | N13: =IF(B13="","",MONTH(B13)) | O13: =IF(B13="","",YEAR(B13)) | P13: =IF(AND(D13<>"",COUNTIF(D$7:D13,D13)=1),MAX(P$6:P12)+1,"") | Q13: =IF(E13="","",IF(I13="أجور عمال","أجرة","مادة"))
A14: =IF(E14="","",ROW()-6) | C14: =IF(B14="","",CHOOSE(WEEKDAY(B14,1),"الأحد","الاثنين","الثلاثاء","الأربعاء","الخميس","الجمعة","السبت")) | H14: =IF(OR(F14="",G14=""),"",ROUND(F14*G14,2)) | I14: =IF(ISNUMBER(SEARCH("ستاند",D14)),"أثاث وستاندات","") | J14: =IF(E14="","",IF(I14="","⚠ عبّي الغرض",IF(AND(D14<>"",OR(ISNUMBER(SEARCH("صيانة",D14)),ISNUMBER(SEARCH("تعزيل",D14)),ISNUMBER(SEARCH("تنظيف",D14)),ISNUMBER(SEARCH("تصليح",D14)))),"⚠ الصيانة بلا ورشة",IF(H14="","⚠ ناقص",IF(D14<>"",IF(SUMIF($D$7:$D$806,D14,$H$7:$H$806)>=20,"أصل","مصروف"),IFERROR(IF(VLOOKUP(I14,'القوائم'!$A$2:$D$14,4,0)="زكاة وصدقة","زكاة وصدقة",IF(AND(VLOOKUP(I14,'القوائم'!$A$2:$D$14,3,0)<>"",H14>=20),"أصل","مصروف")),"مصروف")))))) | N14: =IF(B14="","",MONTH(B14)) | O14: =IF(B14="","",YEAR(B14)) | P14: =IF(AND(D14<>"",COUNTIF(D$7:D14,D14)=1),MAX(P$6:P13)+1,"") | Q14: =IF(E14="","",IF(I14="أجور عمال","أجرة","مادة"))
A15: =IF(E15="","",ROW()-6) | C15: =IF(B15="","",CHOOSE(WEEKDAY(B15,1),"الأحد","الاثنين","الثلاثاء","الأربعاء","الخميس","الجمعة","السبت")) | H15: =IF(OR(F15="",G15=""),"",ROUND(F15*G15,2)) | I15: =IF(ISNUMBER(SEARCH("ستاند",D15)),"أثاث وستاندات","") | J15: =IF(E15="","",IF(I15="","⚠ عبّي الغرض",IF(AND(D15<>"",OR(ISNUMBER(SEARCH("صيانة",D15)),ISNUMBER(SEARCH("تعزيل",D15)),ISNUMBER(SEARCH("تنظيف",D15)),ISNUMBER(SEARCH("تصليح",D15)))),"⚠ الصيانة بلا ورشة",IF(H15="","⚠ ناقص",IF(D15<>"",IF(SUMIF($D$7:$D$806,D15,$H$7:$H$806)>=20,"أصل","مصروف"),IFERROR(IF(VLOOKUP(I15,'القوائم'!$A$2:$D$14,4,0)="زكاة وصدقة","زكاة وصدقة",IF(AND(VLOOKUP(I15,'القوائم'!$A$2:$D$14,3,0)<>"",H15>=20),"أصل","مصروف")),"مصروف")))))) | N15: =IF(B15="","",MONTH(B15)) | O15: =IF(B15="","",YEAR(B15)) | P15: =IF(AND(D15<>"",COUNTIF(D$7:D15,D15)=1),MAX(P$6:P14)+1,"") | Q15: =IF(E15="","",IF(I15="أجور عمال","أجرة","مادة"))
A16: =IF(E16="","",ROW()-6) | C16: =IF(B16="","",CHOOSE(WEEKDAY(B16,1),"الأحد","الاثنين","الثلاثاء","الأربعاء","الخميس","الجمعة","السبت")) | H16: =IF(OR(F16="",G16=""),"",ROUND(F16*G16,2)) | I16: =IF(ISNUMBER(SEARCH("ستاند",D16)),"أثاث وستاندات","") | J16: =IF(E16="","",IF(I16="","⚠ عبّي الغرض",IF(AND(D16<>"",OR(ISNUMBER(SEARCH("صيانة",D16)),ISNUMBER(SEARCH("تعزيل",D16)),ISNUMBER(SEARCH("تنظيف",D16)),ISNUMBER(SEARCH("تصليح",D16)))),"⚠ الصيانة بلا ورشة",IF(H16="","⚠ ناقص",IF(D16<>"",IF(SUMIF($D$7:$D$806,D16,$H$7:$H$806)>=20,"أصل","مصروف"),IFERROR(IF(VLOOKUP(I16,'القوائم'!$A$2:$D$14,4,0)="زكاة وصدقة","زكاة وصدقة",IF(AND(VLOOKUP(I16,'القوائم'!$A$2:$D$14,3,0)<>"",H16>=20),"أصل","مصروف")),"مصروف")))))) | N16: =IF(B16="","",MONTH(B16)) | O16: =IF(B16="","",YEAR(B16)) | P16: =IF(AND(D16<>"",COUNTIF(D$7:D16,D16)=1),MAX(P$6:P15)+1,"") | Q16: =IF(E16="","",IF(I16="أجور عمال","أجرة","مادة"))
A17: =IF(E17="","",ROW()-6) | C17: =IF(B17="","",CHOOSE(WEEKDAY(B17,1),"الأحد","الاثنين","الثلاثاء","الأربعاء","الخميس","الجمعة","السبت")) | H17: =IF(OR(F17="",G17=""),"",ROUND(F17*G17,2)) | I17: =IF(ISNUMBER(SEARCH("ستاند",D17)),"أثاث وستاندات","") | J17: =IF(E17="","",IF(I17="","⚠ عبّي الغرض",IF(AND(D17<>"",OR(ISNUMBER(SEARCH("صيانة",D17)),ISNUMBER(SEARCH("تعزيل",D17)),ISNUMBER(SEARCH("تنظيف",D17)),ISNUMBER(SEARCH("تصليح",D17)))),"⚠ الصيانة بلا ورشة",IF(H17="","⚠ ناقص",IF(D17<>"",IF(SUMIF($D$7:$D$806,D17,$H$7:$H$806)>=20,"أصل","مصروف"),IFERROR(IF(VLOOKUP(I17,'القوائم'!$A$2:$D$14,4,0)="زكاة وصدقة","زكاة وصدقة",IF(AND(VLOOKUP(I17,'القوائم'!$A$2:$D$14,3,0)<>"",H17>=20),"أصل","مصروف")),"مصروف")))))) | N17: =IF(B17="","",MONTH(B17)) | O17: =IF(B17="","",YEAR(B17)) | P17: =IF(AND(D17<>"",COUNTIF(D$7:D17,D17)=1),MAX(P$6:P16)+1,"") | Q17: =IF(E17="","",IF(I17="أجور عمال","أجرة","مادة"))
A18: =IF(E18="","",ROW()-6) | C18: =IF(B18="","",CHOOSE(WEEKDAY(B18,1),"الأحد","الاثنين","الثلاثاء","الأربعاء","الخميس","الجمعة","السبت")) | H18: =IF(OR(F18="",G18=""),"",ROUND(F18*G18,2)) | I18: =IF(ISNUMBER(SEARCH("ستاند",D18)),"أثاث وستاندات","") | J18: =IF(E18="","",IF(I18="","⚠ عبّي الغرض",IF(AND(D18<>"",OR(ISNUMBER(SEARCH("صيانة",D18)),ISNUMBER(SEARCH("تعزيل",D18)),ISNUMBER(SEARCH("تنظيف",D18)),ISNUMBER(SEARCH("تصليح",D18)))),"⚠ الصيانة بلا ورشة",IF(H18="","⚠ ناقص",IF(D18<>"",IF(SUMIF($D$7:$D$806,D18,$H$7:$H$806)>=20,"أصل","مصروف"),IFERROR(IF(VLOOKUP(I18,'القوائم'!$A$2:$D$14,4,0)="زكاة وصدقة","زكاة وصدقة",IF(AND(VLOOKUP(I18,'القوائم'!$A$2:$D$14,3,0)<>"",H18>=20),"أصل","مصروف")),"مصروف")))))) | N18: =IF(B18="","",MONTH(B18)) | O18: =IF(B18="","",YEAR(B18)) | P18: =IF(AND(D18<>"",COUNTIF(D$7:D18,D18)=1),MAX(P$6:P17)+1,"") | Q18: =IF(E18="","",IF(I18="أجور عمال","أجرة","مادة"))
... A806: =IF(E806="","",ROW()-6) | C806: =IF(B806="","",CHOOSE(WEEKDAY(B806,1),"الأحد","الاثنين","الثلاثاء","الأربعاء","الخميس","الجمعة","السبت")) | H806: =IF(OR(F806="",G806=""),"",ROUND(F806*G806,2)) | I806: =IF(ISNUMBER(SEARCH("ستاند",D806)),"أثاث وستاندات","") | J806: =IF(E806="","",IF(I806="","⚠ عبّي الغرض",IF(AND(D806<>"",OR(ISNUMBER(SEARCH("صيانة",D806)),ISNUMBER(SEARCH("تعزيل",D806)),ISNUMBER(SEARCH("تنظيف",D806)),ISNUMBER(SEARCH("تصليح",D806)))),"⚠ الصيانة بلا ورشة",IF(H806="","⚠ ناقص",IF(D806<>"",IF(SUMIF($D$7:$D$806,D806,$H$7:$H$806)>=20,"أصل","مصروف"),IFERROR(IF(VLOOKUP(I806,'القوائم'!$A$2:$D$14,4,0)="زكاة وصدقة","زكاة وصدقة",IF(AND(VLOOKUP(I806,'القوائم'!$A$2:$D$14,3,0)<>"",H806>=20),"أصل","مصروف")),"مصروف")))))) | N806: =IF(B806="","",MONTH(B806)) | O806: =IF(B806="","",YEAR(B806)) | P806: =IF(AND(D806<>"",COUNTIF(D$7:D806,D806)=1),MAX(P$6:P805)+1,"") | Q806: =IF(E806="","",IF(I806="أجور عمال","أجرة","مادة"))

Sheet الملخص
A1: ملخص التكاليف التشغيلية — شهر بشهر
A3: السنة | B3: 2026
A5: الشهر | B5: مصروف | C5: أصول (20+) | D5: زكاة وصدقة | E5: أجور عمال | F5: المجموع
A6: 01 — كانون الثاني | B6: =SUMIFS('التكاليف'!$H$7:$H$806,'التكاليف'!$N$7:$N$806,1,'التكاليف'!$O$7:$O$806,$B$3,'التكاليف'!$J$7:$J$806,"مصروف",'التكاليف'!$Q$7:$Q$806,"مادة") | C6: =SUMIFS('التكاليف'!$H$7:$H$806,'التكاليف'!$N$7:$N$806,1,'التكاليف'!$O$7:$O$806,$B$3,'التكاليف'!$J$7:$J$806,"أصل") | D6: =SUMIFS('التكاليف'!$H$7:$H$806,'التكاليف'!$N$7:$N$806,1,'التكاليف'!$O$7:$O$806,$B$3,'التكاليف'!$J$7:$J$806,"زكاة وصدقة") | E6: =SUMIFS('التكاليف'!$H$7:$H$806,'التكاليف'!$N$7:$N$806,1,'التكاليف'!$O$7:$O$806,$B$3,'التكاليف'!$J$7:$J$806,"مصروف",'التكاليف'!$Q$7:$Q$806,"أجرة") | F6: =SUM(B6:E6)
A7: 02 — شباط | B7: =SUMIFS('التكاليف'!$H$7:$H$806,'التكاليف'!$N$7:$N$806,2,'التكاليف'!$O$7:$O$806,$B$3,'التكاليف'!$J$7:$J$806,"مصروف",'التكاليف'!$Q$7:$Q$806,"مادة") | C7: =SUMIFS('التكاليف'!$H$7:$H$806,'التكاليف'!$N$7:$N$806,2,'التكاليف'!$O$7:$O$806,$B$3,'التكاليف'!$J$7:$J$806,"أصل") | D7: =SUMIFS('التكاليف'!$H$7:$H$806,'التكاليف'!$N$7:$N$806,2,'التكاليف'!$O$7:$O$806,$B$3,'التكاليف'!$J$7:$J$806,"زكاة وصدقة") | E7: =SUMIFS('التكاليف'!$H$7:$H$806,'التكاليف'!$N$7:$N$806,2,'التكاليف'!$O$7:$O$806,$B$3,'التكاليف'!$J$7:$J$806,"مصروف",'التكاليف'!$Q$7:$Q$806,"أجرة") | F7: =SUM(B7:E7)
A8: 03 — آذار | B8: =SUMIFS('التكاليف'!$H$7:$H$806,'التكاليف'!$N$7:$N$806,3,'التكاليف'!$O$7:$O$806,$B$3,'التكاليف'!$J$7:$J$806,"مصروف",'التكاليف'!$Q$7:$Q$806,"مادة") | C8: =SUMIFS('التكاليف'!$H$7:$H$806,'التكاليف'!$N$7:$N$806,3,'التكاليف'!$O$7:$O$806,$B$3,'التكاليف'!$J$7:$J$806,"أصل") | D8: =SUMIFS('التكاليف'!$H$7:$H$806,'التكاليف'!$N$7:$N$806,3,'التكاليف'!$O$7:$O$806,$B$3,'التكاليف'!$J$7:$J$806,"زكاة وصدقة") | E8: =SUMIFS('التكاليف'!$H$7:$H$806,'التكاليف'!$N$7:$N$806,3,'التكاليف'!$O$7:$O$806,$B$3,'التكاليف'!$J$7:$J$806,"مصروف",'التكاليف'!$Q$7:$Q$806,"أجرة") | F8: =SUM(B8:E8)
A9: 04 — نيسان | B9: =SUMIFS('التكاليف'!$H$7:$H$806,'التكاليف'!$N$7:$N$806,4,'التكاليف'!$O$7:$O$806,$B$3,'التكاليف'!$J$7:$J$806,"مصروف",'التكاليف'!$Q$7:$Q$806,"مادة") | C9: =SUMIFS('التكاليف'!$H$7:$H$806,'التكاليف'!$N$7:$N$806,4,'التكاليف'!$O$7:$O$806,$B$3,'التكاليف'!$J$7:$J$806,"أصل") | D9: =SUMIFS('التكاليف'!$H$7:$H$806,'التكاليف'!$N$7:$N$806,4,'التكاليف'!$O$7:$O$806,$B$3,'التكاليف'!$J$7:$J$806,"زكاة وصدقة") | E9: =SUMIFS('التكاليف'!$H$7:$H$806,'التكاليف'!$N$7:$N$806,4,'التكاليف'!$O$7:$O$806,$B$3,'التكاليف'!$J$7:$J$806,"مصروف",'التكاليف'!$Q$7:$Q$806,"أجرة") | F9: =SUM(B9:E9)
A10: 05 — أيار | B10: =SUMIFS('التكاليف'!$H$7:$H$806,'التكاليف'!$N$7:$N$806,5,'التكاليف'!$O$7:$O$806,$B$3,'التكاليف'!$J$7:$J$806,"مصروف",'التكاليف'!$Q$7:$Q$806,"مادة") | C10: =SUMIFS('التكاليف'!$H$7:$H$806,'التكاليف'!$N$7:$N$806,5,'التكاليف'!$O$7:$O$806,$B$3,'التكاليف'!$J$7:$J$806,"أصل") | D10: =SUMIFS('التكاليف'!$H$7:$H$806,'التكاليف'!$N$7:$N$806,5,'التكاليف'!$O$7:$O$806,$B$3,'التكاليف'!$J$7:$J$806,"زكاة وصدقة") | E10: =SUMIFS('التكاليف'!$H$7:$H$806,'التكاليف'!$N$7:$N$806,5,'التكاليف'!$O$7:$O$806,$B$3,'التكاليف'!$J$7:$J$806,"مصروف",'التكاليف'!$Q$7:$Q$806,"أجرة") | F10: =SUM(B10:E10)
A11: 06 — حزيران | B11: =SUMIFS('التكاليف'!$H$7:$H$806,'التكاليف'!$N$7:$N$806,6,'التكاليف'!$O$7:$O$806,$B$3,'التكاليف'!$J$7:$J$806,"مصروف",'التكاليف'!$Q$7:$Q$806,"مادة") | C11: =SUMIFS('التكاليف'!$H$7:$H$806,'التكاليف'!$N$7:$N$806,6,'التكاليف'!$O$7:$O$806,$B$3,'التكاليف'!$J$7:$J$806,"أصل") | D11: =SUMIFS('التكاليف'!$H$7:$H$806,'التكاليف'!$N$7:$N$806,6,'التكاليف'!$O$7:$O$806,$B$3,'التكاليف'!$J$7:$J$806,"زكاة وصدقة") | E11: =SUMIFS('التكاليف'!$H$7:$H$806,'التكاليف'!$N$7:$N$806,6,'التكاليف'!$O$7:$O$806,$B$3,'التكاليف'!$J$7:$J$806,"مصروف",'التكاليف'!$Q$7:$Q$806,"أجرة") | F11: =SUM(B11:E11)
A12: 07 — تموز | B12: =SUMIFS('التكاليف'!$H$7:$H$806,'التكاليف'!$N$7:$N$806,7,'التكاليف'!$O$7:$O$806,$B$3,'التكاليف'!$J$7:$J$806,"مصروف",'التكاليف'!$Q$7:$Q$806,"مادة") | C12: =SUMIFS('التكاليف'!$H$7:$H$806,'التكاليف'!$N$7:$N$806,7,'التكاليف'!$O$7:$O$806,$B$3,'التكاليف'!$J$7:$J$806,"أصل") | D12: =SUMIFS('التكاليف'!$H$7:$H$806,'التكاليف'!$N$7:$N$806,7,'التكاليف'!$O$7:$O$806,$B$3,'التكاليف'!$J$7:$J$806,"زكاة وصدقة") | E12: =SUMIFS('التكاليف'!$H$7:$H$806,'التكاليف'!$N$7:$N$806,7,'التكاليف'!$O$7:$O$806,$B$3,'التكاليف'!$J$7:$J$806,"مصروف",'التكاليف'!$Q$7:$Q$806,"أجرة") | F12: =SUM(B12:E12)
A13: 08 — آب | B13: =SUMIFS('التكاليف'!$H$7:$H$806,'التكاليف'!$N$7:$N$806,8,'التكاليف'!$O$7:$O$806,$B$3,'التكاليف'!$J$7:$J$806,"مصروف",'التكاليف'!$Q$7:$Q$806,"مادة") | C13: =SUMIFS('التكاليف'!$H$7:$H$806,'التكاليف'!$N$7:$N$806,8,'التكاليف'!$O$7:$O$806,$B$3,'التكاليف'!$J$7:$J$806,"أصل") | D13: =SUMIFS('التكاليف'!$H$7:$H$806,'التكاليف'!$N$7:$N$806,8,'التكاليف'!$O$7:$O$806,$B$3,'التكاليف'!$J$7:$J$806,"زكاة وصدقة") | E13: =SUMIFS('التكاليف'!$H$7:$H$806,'التكاليف'!$N$7:$N$806,8,'التكاليف'!$O$7:$O$806,$B$3,'التكاليف'!$J$7:$J$806,"مصروف",'التكاليف'!$Q$7:$Q$806,"أجرة") | F13: =SUM(B13:E13)
A14: 09 — أيلول | B14: =SUMIFS('التكاليف'!$H$7:$H$806,'التكاليف'!$N$7:$N$806,9,'التكاليف'!$O$7:$O$806,$B$3,'التكاليف'!$J$7:$J$806,"مصروف",'التكاليف'!$Q$7:$Q$806,"مادة") | C14: =SUMIFS('التكاليف'!$H$7:$H$806,'التكاليف'!$N$7:$N$806,9,'التكاليف'!$O$7:$O$806,$B$3,'التكاليف'!$J$7:$J$806,"أصل") | D14: =SUMIFS('التكاليف'!$H$7:$H$806,'التكاليف'!$N$7:$N$806,9,'التكاليف'!$O$7:$O$806,$B$3,'التكاليف'!$J$7:$J$806,"زكاة وصدقة") | E14: =SUMIFS('التكاليف'!$H$7:$H$806,'التكاليف'!$N$7:$N$806,9,'التكاليف'!$O$7:$O$806,$B$3,'التكاليف'!$J$7:$J$806,"مصروف",'التكاليف'!$Q$7:$Q$806,"أجرة") | F14: =SUM(B14:E14)
A15: 10 — تشرين الأول | B15: =SUMIFS('التكاليف'!$H$7:$H$806,'التكاليف'!$N$7:$N$806,10,'التكاليف'!$O$7:$O$806,$B$3,'التكاليف'!$J$7:$J$806,"مصروف",'التكاليف'!$Q$7:$Q$806,"مادة") | C15: =SUMIFS('التكاليف'!$H$7:$H$806,'التكاليف'!$N$7:$N$806,10,'التكاليف'!$O$7:$O$806,$B$3,'التكاليف'!$J$7:$J$806,"أصل") | D15: =SUMIFS('التكاليف'!$H$7:$H$806,'التكاليف'!$N$7:$N$806,10,'التكاليف'!$O$7:$O$806,$B$3,'التكاليف'!$J$7:$J$806,"زكاة وصدقة") | E15: =SUMIFS('التكاليف'!$H$7:$H$806,'التكاليف'!$N$7:$N$806,10,'التكاليف'!$O$7:$O$806,$B$3,'التكاليف'!$J$7:$J$806,"مصروف",'التكاليف'!$Q$7:$Q$806,"أجرة") | F15: =SUM(B15:E15)
A16: 11 — تشرين الثاني | B16: =SUMIFS('التكاليف'!$H$7:$H$806,'التكاليف'!$N$7:$N$806,11,'التكاليف'!$O$7:$O$806,$B$3,'التكاليف'!$J$7:$J$806,"مصروف",'التكاليف'!$Q$7:$Q$806,"مادة") | C16: =SUMIFS('التكاليف'!$H$7:$H$806,'التكاليف'!$N$7:$N$806,11,'التكاليف'!$O$7:$O$806,$B$3,'التكاليف'!$J$7:$J$806,"أصل") | D16: =SUMIFS('التكاليف'!$H$7:$H$806,'التكاليف'!$N$7:$N$806,11,'التكاليف'!$O$7:$O$806,$B$3,'التكاليف'!$J$7:$J$806,"زكاة وصدقة") | E16: =SUMIFS('التكاليف'!$H$7:$H$806,'التكاليف'!$N$7:$N$806,11,'التكاليف'!$O$7:$O$806,$B$3,'التكاليف'!$J$7:$J$806,"مصروف",'التكاليف'!$Q$7:$Q$806,"أجرة") | F16: =SUM(B16:E16)
A17: 12 — كانون الأول | B17: =SUMIFS('التكاليف'!$H$7:$H$806,'التكاليف'!$N$7:$N$806,12,'التكاليف'!$O$7:$O$806,$B$3,'التكاليف'!$J$7:$J$806,"مصروف",'التكاليف'!$Q$7:$Q$806,"مادة") | C17: =SUMIFS('التكاليف'!$H$7:$H$806,'التكاليف'!$N$7:$N$806,12,'التكاليف'!$O$7:$O$806,$B$3,'التكاليف'!$J$7:$J$806,"أصل") | D17: =SUMIFS('التكاليف'!$H$7:$H$806,'التكاليف'!$N$7:$N$806,12,'التكاليف'!$O$7:$O$806,$B$3,'التكاليف'!$J$7:$J$806,"زكاة وصدقة") | E17: =SUMIFS('التكاليف'!$H$7:$H$806,'التكاليف'!$N$7:$N$806,12,'التكاليف'!$O$7:$O$806,$B$3,'التكاليف'!$J$7:$J$806,"مصروف",'التكاليف'!$Q$7:$Q$806,"أجرة") | F17: =SUM(B17:E17)
A18: مجموع السنة | B18: =SUM(B6:B17) | C18: =SUM(C6:C17) | D18: =SUM(D6:D17) | E18: =SUM(E6:E17) | F18: =SUM(F6:F17)
A19: الشهر حسب التاريخ · أجور الورشات اللي صارت أصل بعمود «أصول» · الزكاة والصدقة لحالها.
A21: الغرض (بلا الورشات) | B21: المبلغ (السنة)
A22: ضيافة | B22: =SUMIFS('التكاليف'!$H$7:$H$806,'التكاليف'!$I$7:$I$806,A22,'التكاليف'!$O$7:$O$806,$B$3,'التكاليف'!$D$7:$D$806,"")
A23: هدايا | B23: =SUMIFS('التكاليف'!$H$7:$H$806,'التكاليف'!$I$7:$I$806,A23,'التكاليف'!$O$7:$O$806,$B$3,'التكاليف'!$D$7:$D$806,"")
A24: إيجار | B24: =SUMIFS('التكاليف'!$H$7:$H$806,'التكاليف'!$I$7:$I$806,A24,'التكاليف'!$O$7:$O$806,$B$3,'التكاليف'!$D$7:$D$806,"")
A25: فاتورة كهرباء | B25: =SUMIFS('التكاليف'!$H$7:$H$806,'التكاليف'!$I$7:$I$806,A25,'التكاليف'!$O$7:$O$806,$B$3,'التكاليف'!$D$7:$D$806,"")
A26: أثاث وستاندات | B26: =SUMIFS('التكاليف'!$H$7:$H$806,'التكاليف'!$I$7:$I$806,A26,'التكاليف'!$O$7:$O$806,$B$3,'التكاليف'!$D$7:$D$806,"")
A27: صيانة المحل | B27: =SUMIFS('التكاليف'!$H$7:$H$806,'التكاليف'!$I$7:$I$806,A27,'التكاليف'!$O$7:$O$806,$B$3,'التكاليف'!$D$7:$D$806,"")
A28: أجور عمال | B28: =SUMIFS('التكاليف'!$H$7:$H$806,'التكاليف'!$I$7:$I$806,A28,'التكاليف'!$O$7:$O$806,$B$3,'التكاليف'!$D$7:$D$806,"")
A29: أجور توصيل | B29: =SUMIFS('التكاليف'!$H$7:$H$806,'التكاليف'!$I$7:$I$806,A29,'التكاليف'!$O$7:$O$806,$B$3,'التكاليف'!$D$7:$D$806,"")
A30: صدقة | B30: =SUMIFS('التكاليف'!$H$7:$H$806,'التكاليف'!$I$7:$I$806,A30,'التكاليف'!$O$7:$O$806,$B$3,'التكاليف'!$D$7:$D$806,"")
A31: زكاة | B31: =SUMIFS('التكاليف'!$H$7:$H$806,'التكاليف'!$I$7:$I$806,A31,'التكاليف'!$O$7:$O$806,$B$3,'التكاليف'!$D$7:$D$806,"")
A32: رسوم تراخيص | B32: =SUMIFS('التكاليف'!$H$7:$H$806,'التكاليف'!$I$7:$I$806,A32,'التكاليف'!$O$7:$O$806,$B$3,'التكاليف'!$D$7:$D$806,"")
A33: توالف بضاعة | B33: =SUMIFS('التكاليف'!$H$7:$H$806,'التكاليف'!$I$7:$I$806,A33,'التكاليف'!$O$7:$O$806,$B$3,'التكاليف'!$D$7:$D$806,"")
A34: أخرى | B34: =SUMIFS('التكاليف'!$H$7:$H$806,'التكاليف'!$O$7:$O$806,$B$3,'التكاليف'!$D$7:$D$806,"")-SUM(B22:B33)
A35: المجموع | B35: =SUM(B22:B34)
A37: الورشات (شغل داخلي) — بتتعبّى لحالها
A38: الورشة | B38: مواد | C38: أجور عمال | D38: المجموع | E38: أصل؟
A39: =IFERROR(INDEX('التكاليف'!$D$7:$D$806,MATCH(1,'التكاليف'!$P$7:$P$806,0)),"") | B39: =IF(A39="","",SUMIFS('التكاليف'!$H$7:$H$806,'التكاليف'!$D$7:$D$806,A39,'التكاليف'!$Q$7:$Q$806,"مادة")) | C39: =IF(A39="","",SUMIFS('التكاليف'!$H$7:$H$806,'التكاليف'!$D$7:$D$806,A39,'التكاليف'!$Q$7:$Q$806,"أجرة")) | D39: =IF(A39="","",B39+C39) | E39: =IF(A39="","",IF(D39>=20,"أصل","مصروف"))
A40: =IFERROR(INDEX('التكاليف'!$D$7:$D$806,MATCH(2,'التكاليف'!$P$7:$P$806,0)),"") | B40: =IF(A40="","",SUMIFS('التكاليف'!$H$7:$H$806,'التكاليف'!$D$7:$D$806,A40,'التكاليف'!$Q$7:$Q$806,"مادة")) | C40: =IF(A40="","",SUMIFS('التكاليف'!$H$7:$H$806,'التكاليف'!$D$7:$D$806,A40,'التكاليف'!$Q$7:$Q$806,"أجرة")) | D40: =IF(A40="","",B40+C40) | E40: =IF(A40="","",IF(D40>=20,"أصل","مصروف"))
A41: =IFERROR(INDEX('التكاليف'!$D$7:$D$806,MATCH(3,'التكاليف'!$P$7:$P$806,0)),"") | B41: =IF(A41="","",SUMIFS('التكاليف'!$H$7:$H$806,'التكاليف'!$D$7:$D$806,A41,'التكاليف'!$Q$7:$Q$806,"مادة")) | C41: =IF(A41="","",SUMIFS('التكاليف'!$H$7:$H$806,'التكاليف'!$D$7:$D$806,A41,'التكاليف'!$Q$7:$Q$806,"أجرة")) | D41: =IF(A41="","",B41+C41) | E41: =IF(A41="","",IF(D41>=20,"أصل","مصروف"))
A42: =IFERROR(INDEX('التكاليف'!$D$7:$D$806,MATCH(4,'التكاليف'!$P$7:$P$806,0)),"") | B42: =IF(A42="","",SUMIFS('التكاليف'!$H$7:$H$806,'التكاليف'!$D$7:$D$806,A42,'التكاليف'!$Q$7:$Q$806,"مادة")) | C42: =IF(A42="","",SUMIFS('التكاليف'!$H$7:$H$806,'التكاليف'!$D$7:$D$806,A42,'التكاليف'!$Q$7:$Q$806,"أجرة")) | D42: =IF(A42="","",B42+C42) | E42: =IF(A42="","",IF(D42>=20,"أصل","مصروف"))
A43: =IFERROR(INDEX('التكاليف'!$D$7:$D$806,MATCH(5,'التكاليف'!$P$7:$P$806,0)),"") | B43: =IF(A43="","",SUMIFS('التكاليف'!$H$7:$H$806,'التكاليف'!$D$7:$D$806,A43,'التكاليف'!$Q$7:$Q$806,"مادة")) | C43: =IF(A43="","",SUMIFS('التكاليف'!$H$7:$H$806,'التكاليف'!$D$7:$D$806,A43,'التكاليف'!$Q$7:$Q$806,"أجرة")) | D43: =IF(A43="","",B43+C43) | E43: =IF(A43="","",IF(D43>=20,"أصل","مصروف"))
A44: =IFERROR(INDEX('التكاليف'!$D$7:$D$806,MATCH(6,'التكاليف'!$P$7:$P$806,0)),"") | B44: =IF(A44="","",SUMIFS('التكاليف'!$H$7:$H$806,'التكاليف'!$D$7:$D$806,A44,'التكاليف'!$Q$7:$Q$806,"مادة")) | C44: =IF(A44="","",SUMIFS('التكاليف'!$H$7:$H$806,'التكاليف'!$D$7:$D$806,A44,'التكاليف'!$Q$7:$Q$806,"أجرة")) | D44: =IF(A44="","",B44+C44) | E44: =IF(A44="","",IF(D44>=20,"أصل","مصروف"))
...

Sheet القوائم
A1: الغرض | B1: حساب المصروف | C1: حساب الأصل (20+) | D1: الفئة
A2: ضيافة | B2: 501106 | D2: مصروف
A3: هدايا | B3: 500701 | D3: مصروف
A4: إيجار | B4: 500402 | D4: مصروف
A5: فاتورة كهرباء | B5: 500403 | D5: مصروف
A6: أثاث وستاندات | B6: 501106 | C6: 100604 | D6: مصروف
A7: صيانة المحل | B7: 501103 | D7: مصروف
A8: أجور عمال | B8: 500312 | D8: مصروف
A9: أجور توصيل | B9: 500802 | D9: مصروف
A10: صدقة | B10: 500910 | D10: زكاة وصدقة
A11: زكاة | B11: 500912 | D11: زكاة وصدقة
A12: رسوم تراخيص | B12: 500503 | D12: مصروف
A13: توالف بضاعة | B13: 500905 | D13: مصروف
A14: أخرى | B14: 500907 | D14: مصروف

Sheet التعليمات
A1: طريقة العمل
A3: ورقة «التكاليف» — كل مصروف أو أجرة بسطر (الأعمدة: # · التاريخ · اليوم · الورشة · البند · الكمية · الإفرادي · الإجمالي · الغرض · أصل؟ · المدقق · ملاحظات)
A4: 1 | B4: كل سطر: البند أو المهمة · الكمية · الإفرادي · التاريخ · الغرض · وبآخر خانة «ملاحظات إضافية»: شو هو، ليش، ولوين راح.
A5: 2 | B5: الإفرادي = الكلفة (من المحل) أو سعر الشراء (من برّا).
A6: 3 | B6: أجرة عامل: سطر زي أي بند — اكتب بالبند اسم العامل والشغلة (مثلاً «احمد النجار — خزائن خشب») · الكمية 1 والإفرادي = المبلغ · الغرض «أجور عمال» · بأي يوم حتى الجمعة.
A7: 4 | B7: الغرض من القائمة — وإذا مش موجود اكتبه بإيدك (مثلاً «أكياس للمحل») وبينحسب «أخرى» · الفاضي بيصير أحمر و«⚠ عبّي الغرض».
A8: 5 | B8: فاتورة/إيجار/زكاة: الكمية 1 والإفرادي = المبلغ · الإيجار: التحويش اليومي ما بينكتب — يوم الدفع سطر بالمبلغ كامل.
A9: 6 | B9: الكمية رقم صحيح بلا فاصلة · الإفرادي والإجمالي منزلتين · الدفع نقدي — إذا تحويل كليك أو شيك اكتبها بالملاحظات.
A10: الورشة (شغل داخلي) — لما نبني إشي للمحل (مثلاً ستاندات)
A11: 7 | B11: اكتب اسم الورشة بأول عمود على كل مادة وكل أجرة إلها (والأجرة غرضها «أجور عمال») — نفس الاسم بالزبط كل مرة. فيها «ستاندات» ← الغرض «أثاث وستاندات» لحاله.
A12: 8 | B12: مجموع الورشة (مواد + أجور) 20 وفوق = كل أسطرها «أصل» · أقل = مصروف · الورشة بس لبناء أو شراء إشي جديد: التصليح والتعزيل والتنظيف بلا ورشة (اسم ورشة فيه «صيانة» أو «تعزيل» بيصير أحمر).
A13: 9 | B13: الفلتر على العناوين: اختار ورشة أو غرض (مثلاً «أجور عمال») وبيطلعوا أسطره لحاله.
A14: التدقيق وأودو والملخص
A15: 10 | B15: الخانة الحمرا = ناقصة · المدقق بيختار اسمه بعد ما يتأكد ← السطر بيصير أخضر · بس الأسطر المدقّقة بتنزل على أودو.
A16: 11 | B16: آخر الشهر (بأمر صاحب المحل): كل سطر بينزل قيد لحاله على حسابه · المرحّل من قبل ما بيتكرّر.
A17: 12 | B17: «الملخص» شهر بشهر: مصروف · أصول · زكاة وصدقة · أجور عمال — وتحته حسب الغرض والورشات. الملخص والتعليمات مقفولين بكلمة السر.
A19: # | B19: الغرض | C19: أمثلة
A20: 1 | B20: ضيافة | C20: شاي · قهوة · مي · سكر · غدا للعمال
A21: 2 | B21: هدايا | C21: هدية لزبون · عيّنات · كاتالوجات
A22: 3 | B22: إيجار | C22: إيجار المستودعات — يوم الدفع بالمبلغ كامل (التحويش اليومي ما بينكتب)
A23: 4 | B23: فاتورة كهرباء | C23: فاتورة الكهربا (والمي) — اكتب أي ساعة بالبند
A24: 5 | B24: أثاث وستاندات | C24: ستاند · رف · مكتب · كرسي · كمبيوتر (20 وفوق = أصل)
A25: 6 | B25: صيانة المحل | C25: تصليح · سباكة · كهربا · دهان · لمبات · قطع غيار
A26: 7 | B26: أجور عمال | C26: تعزيل · تنظيف · تحميل · نجّار · كهربجي من برّا — اسم العامل والشغلة بالبند
A27: 8 | B27: أجور توصيل | C27: أجرة سيارة · توصيل · بنزين للتوصيل
A28: 9 | B28: صدقة | C28: صدقة · تبرع لجامع أو جمعية (كاش أو بضاعة بالكلفة)
A29: 10 | B29: زكاة | C29: زكاة المحل السنوية
A30: 11 | B30: رسوم تراخيص | C30: رخصة المهن · البلدية · الغرفة
A31: 12 | B31: توالف بضاعة | C31: بضاعة انكسرت أو خربت بالمحل (بالكلفة)
A32: 13 | B32: أخرى | C32: أي إشي ثاني — أو اكتب الغرض بإيدك بالخانة (مثلاً «أكياس للمحل»)
