Workbook

Sheet التسوية
A1: نظام الموظفين — التسوية الأسبوعية والشهرية
B3: اختر الشهر | C3: 10 | D3: اختر السنة | E3: 2026 | F3: ← أول شي اختار الشهر والسنة — كل الملف (الأسابيع وتواريخ الأيام) بيتبرمج عليهم
B5: الأسبوع | C5: الأسبوع الأول | N5: =IFERROR(MIN(MATCH($C$5,القوائم!$K$11:$K$16,0),NW),1) -> 1
A7: افتتاح الشهر — انقل الأرقام من «إقفال الشهر» بملف الشهر الماضي
A8: الموظف | B8: مستحق له لسا ما قبضه (دينار) | C8: قرض أو دين متبقي عليه (دينار) | D8: القسط الأسبوعي (دينار) | E8: «مستحق له» = أيام اشتغلها آخر الشهر الماضي وما انقبضت (مثلاً أسبوع مقطوع). بينضاف لصافي أول أسبوع. · «دين متبقي» = اللي ضل عليه من ديون وبضاعة. بينخصم منه القسط الأسبوعي لحد ما يخلص.
A9: عمر المصري | B9: 0 | C9: 0 | D9: 0
A10: عبدالعزيز | B10: 0 | C10: 0 | D10: 0
A12: ="تسوية الأسبوع المختار · "&$C$5 -> تسوية الأسبوع المختار · الأسبوع الأول
A13: الموظف | B13: عدد الساعات | C13: المستحق (دينار) | D13: + مدوّر | E13: − مقبوض يومياً | F13: − السلف | G13: − القسط | H13: الصافي للدفع | I13: المدفوع (دينار) | J13: الباقي له | K13: الدين المتبقي | L13: ملاحظة
A14: عمر المصري | B14: =N(INDEX(B22:B27,WK)) -> 0 | C14: =N(INDEX(C22:C27,WK)) -> 0 | D14: =N(INDEX(D22:D27,WK)) -> 0 | E14: 0 | F14: =N(INDEX(E22:E27,WK)) -> 0 | G14: =N(INDEX(F22:F27,WK)) -> 0 | H14: =N(INDEX(G22:G27,WK)) -> 0 | I14: =N(INDEX(H22:H27,WK)) -> 0 | J14: =N(INDEX(I22:I27,WK)) -> 0 | K14: =N(INDEX(J22:J27,WK)) -> 0 | L14: =IF(AND(ADV_CAP>0,C14>0,F14>ADV_CAP*C14),"⚠️ السلف فوق السقف",IF(H14<0,"⚠️ السلف أكثر من المستحق",IF(AND(H14>0,J14=0),"✔ مدفوع",IF(H14>0,"لسا ما اندفع",""))))
A15: عبدالعزيز | B15: =N(INDEX(B32:B37,WK)) -> 0 | C15: =N(INDEX(C32:C37,WK)) -> 0 | D15: =N(INDEX(D32:D37,WK)) -> 0 | E15: =N(INDEX(E32:E37,WK)) -> 0 | F15: =N(INDEX(F32:F37,WK)) -> 0 | G15: =N(INDEX(G32:G37,WK)) -> 0 | H15: =N(INDEX(H32:H37,WK)) -> 0 | I15: =N(INDEX(I32:I37,WK)) -> 0 | ... K15: =N(INDEX(K32:K37,WK)) -> 0 | L15: =IF(AND(ADV_CAP>0,C15>0,F15>ADV_CAP*C15),"⚠️ السلف فوق السقف",IF(H15<0,"⚠️ السلف أكثر من المستحق",IF(AND(H15>0,J15=0),"✔ مدفوع",IF(H15>0,"لسا ما اندفع",""))))
A17: المدفوع بينكتب بجداول الشهر تحت (سطر الأسبوع) — وهون بيطلع لحاله. المدير بورقته لحال · عمال المهام بورقتهم.
A20: عمر المصري — كل أسابيع الشهر
A21: الأسبوع | B21: عدد الساعات | C21: المستحق (دينار) | D21: + مدوّر | E21: − السلف | F21: − القسط | G21: الصافي للدفع | H21: المدفوع (دينار) | I21: الباقي له | J21: الدين المتبقي | K21: ملاحظة
A22: =IF(1<=NW,"الأسبوع الأول","") -> الأسبوع الأول | B22: =IF(1<=NW,N('ساعات عمر'!E14),"") -> 0 | C22: =IF(1<=NW,N('ساعات عمر'!H15),"") -> 0 | D22: =IF(1<=NW,$B$9,"") -> 0 | E22: =IF(1<=NW,SUMIFS(ADV_AMT,ADV_E,"عمر المصري",ADV_D,">="&القوائم!$H$11,ADV_D,"<="&القوائم!$I$11),"") -> 0 | F22: =IF(1<=NW,IF(N(C22)=0,0,MAX(0,MIN(IF(_xlfn.MAXIFS(LG_IDX,LG_E,"عمر المصري",LG_INST,"<>",LG_D,"<="&القوائم!$I$11)=0,$D$9,INDEX(LG_INST,_xlfn.MAXIFS(LG_IDX,LG_E,"عمر المصري",LG_INST,"<>",LG_D,"<="&القوائم!$I$11))),$C$9+SUMIFS(LG_DEBT,LG_E,"عمر المصري",LG_D,"<="&القوائم!$I$11)-SUMIFS(LG_REP,LG_E,"عمر المصري",LG_D,"<="&القوائم!$I$11)-0,N(C22)+N(D22)-N(E22)))),"") -> 0 | G22: =IF(1<=NW,C22+D22-E22-F22,"") -> 0 | I22: =IF(1<=NW,G22-N(H22),"") -> 0 | J22: =IF(1<=NW,MAX(0,$C$9+SUMIFS(LG_DEBT,LG_E,"عمر المصري",LG_D,"<="&القوائم!$I$11)-SUMIFS(LG_REP,LG_E,"عمر المصري",LG_D,"<="&القوائم!$I$11)-SUM(F22:F22)),"") -> 0 | K22: =IF(1<=NW,IF(AND(ADV_CAP>0,C22>0,E22>ADV_CAP*C22),"⚠️ السلف فوق السقف",IF(G22<0,"⚠️ السلف أكثر من المستحق","")),"")
A23: =IF(2<=NW,"الأسبوع الثاني","") -> الأسبوع الثاني | B23: =IF(2<=NW,N('ساعات عمر'!E24),"") -> 0 | C23: =IF(2<=NW,N('ساعات عمر'!H25),"") -> 0 | D23: =IF(2<=NW,0,"") -> 0 | E23: =IF(2<=NW,SUMIFS(ADV_AMT,ADV_E,"عمر المصري",ADV_D,">="&القوائم!$H$12,ADV_D,"<="&القوائم!$I$12),"") -> 0 | F23: =IF(2<=NW,IF(N(C23)=0,0,MAX(0,MIN(IF(_xlfn.MAXIFS(LG_IDX,LG_E,"عمر المصري",LG_INST,"<>",LG_D,"<="&القوائم!$I$12)=0,$D$9,INDEX(LG_INST,_xlfn.MAXIFS(LG_IDX,LG_E,"عمر المصري",LG_INST,"<>",LG_D,"<="&القوائم!$I$12))),$C$9+SUMIFS(LG_DEBT,LG_E,"عمر المصري",LG_D,"<="&القوائم!$I$12)-SUMIFS(LG_REP,LG_E,"عمر المصري",LG_D,"<="&القوائم!$I$12)-SUM(F22:F22),N(C23)+N(D23)-N(E23)))),"") -> 0 | G23: =IF(2<=NW,C23+D23-E23-F23,"") -> 0 | I23: =IF(2<=NW,G23-N(H23),"") -> 0 | J23: =IF(2<=NW,MAX(0,$C$9+SUMIFS(LG_DEBT,LG_E,"عمر المصري",LG_D,"<="&القوائم!$I$12)-SUMIFS(LG_REP,LG_E,"عمر المصري",LG_D,"<="&القوائم!$I$12)-SUM(F22:F23)),"") -> 0 | K23: =IF(2<=NW,IF(AND(ADV_CAP>0,C23>0,E23>ADV_CAP*C23),"⚠️ السلف فوق السقف",IF(G23<0,"⚠️ السلف أكثر من المستحق","")),"")
A24: =IF(3<=NW,"الأسبوع الثالث","") -> الأسبوع الثالث | B24: =IF(3<=NW,N('ساعات عمر'!E34),"") -> 0 | C24: =IF(3<=NW,N('ساعات عمر'!H35),"") -> 0 | D24: =IF(3<=NW,0,"") -> 0 | E24: =IF(3<=NW,SUMIFS(ADV_AMT,ADV_E,"عمر المصري",ADV_D,">="&القوائم!$H$13,ADV_D,"<="&القوائم!$I$13),"") -> 0 | F24: =IF(3<=NW,IF(N(C24)=0,0,MAX(0,MIN(IF(_xlfn.MAXIFS(LG_IDX,LG_E,"عمر المصري",LG_INST,"<>",LG_D,"<="&القوائم!$I$13)=0,$D$9,INDEX(LG_INST,_xlfn.MAXIFS(LG_IDX,LG_E,"عمر المصري",LG_INST,"<>",LG_D,"<="&القوائم!$I$13))),$C$9+SUMIFS(LG_DEBT,LG_E,"عمر المصري",LG_D,"<="&القوائم!$I$13)-SUMIFS(LG_REP,LG_E,"عمر المصري",LG_D,"<="&القوائم!$I$13)-SUM(F22:F23),N(C24)+N(D24)-N(E24)))),"") -> 0 | G24: =IF(3<=NW,C24+D24-E24-F24,"") -> 0 | I24: =IF(3<=NW,G24-N(H24),"") -> 0 | J24: =IF(3<=NW,MAX(0,$C$9+SUMIFS(LG_DEBT,LG_E,"عمر المصري",LG_D,"<="&القوائم!$I$13)-SUMIFS(LG_REP,LG_E,"عمر المصري",LG_D,"<="&القوائم!$I$13)-SUM(F22:F24)),"") -> 0 | K24: =IF(3<=NW,IF(AND(ADV_CAP>0,C24>0,E24>ADV_CAP*C24),"⚠️ السلف فوق السقف",IF(G24<0,"⚠️ السلف أكثر من المستحق","")),"")
A25: =IF(4<=NW,"الأسبوع الرابع","") -> الأسبوع الرابع | B25: =IF(4<=NW,N('ساعات عمر'!E44),"") -> 0 | C25: =IF(4<=NW,N('ساعات عمر'!H45),"") -> 0 | D25: =IF(4<=NW,0,"") -> 0 | E25: =IF(4<=NW,SUMIFS(ADV_AMT,ADV_E,"عمر المصري",ADV_D,">="&القوائم!$H$14,ADV_D,"<="&القوائم!$I$14),"") -> 0 | F25: =IF(4<=NW,IF(N(C25)=0,0,MAX(0,MIN(IF(_xlfn.MAXIFS(LG_IDX,LG_E,"عمر المصري",LG_INST,"<>",LG_D,"<="&القوائم!$I$14)=0,$D$9,INDEX(LG_INST,_xlfn.MAXIFS(LG_IDX,LG_E,"عمر المصري",LG_INST,"<>",LG_D,"<="&القوائم!$I$14))),$C$9+SUMIFS(LG_DEBT,LG_E,"عمر المصري",LG_D,"<="&القوائم!$I$14)-SUMIFS(LG_REP,LG_E,"عمر المصري",LG_D,"<="&القوائم!$I$14)-SUM(F22:F24),N(C25)+N(D25)-N(E25)))),"") -> 0 | G25: =IF(4<=NW,C25+D25-E25-F25,"") -> 0 | I25: =IF(4<=NW,G25-N(H25),"") -> 0 | J25: =IF(4<=NW,MAX(0,$C$9+SUMIFS(LG_DEBT,LG_E,"عمر المصري",LG_D,"<="&القوائم!$I$14)-SUMIFS(LG_REP,LG_E,"عمر المصري",LG_D,"<="&القوائم!$I$14)-SUM(F22:F25)),"") -> 0 | K25: =IF(4<=NW,IF(AND(ADV_CAP>0,C25>0,E25>ADV_CAP*C25),"⚠️ السلف فوق السقف",IF(G25<0,"⚠️ السلف أكثر من المستحق","")),"")
A26: =IF(5<=NW,"الأسبوع الخامس","") -> الأسبوع الخامس | B26: =IF(5<=NW,N('ساعات عمر'!E54),"") -> 0 | C26: =IF(5<=NW,N('ساعات عمر'!H55),"") -> 0 | D26: =IF(5<=NW,0,"") -> 0 | E26: =IF(5<=NW,SUMIFS(ADV_AMT,ADV_E,"عمر المصري",ADV_D,">="&القوائم!$H$15,ADV_D,"<="&القوائم!$I$15),"") -> 0 | F26: =IF(5<=NW,IF(N(C26)=0,0,MAX(0,MIN(IF(_xlfn.MAXIFS(LG_IDX,LG_E,"عمر المصري",LG_INST,"<>",LG_D,"<="&القوائم!$I$15)=0,$D$9,INDEX(LG_INST,_xlfn.MAXIFS(LG_IDX,LG_E,"عمر المصري",LG_INST,"<>",LG_D,"<="&القوائم!$I$15))),$C$9+SUMIFS(LG_DEBT,LG_E,"عمر المصري",LG_D,"<="&القوائم!$I$15)-SUMIFS(LG_REP,LG_E,"عمر المصري",LG_D,"<="&القوائم!$I$15)-SUM(F22:F25),N(C26)+N(D26)-N(E26)))),"") -> 0 | G26: =IF(5<=NW,C26+D26-E26-F26,"") -> 0 | I26: =IF(5<=NW,G26-N(H26),"") -> 0 | J26: =IF(5<=NW,MAX(0,$C$9+SUMIFS(LG_DEBT,LG_E,"عمر المصري",LG_D,"<="&القوائم!$I$15)-SUMIFS(LG_REP,LG_E,"عمر المصري",LG_D,"<="&القوائم!$I$15)-SUM(F22:F26)),"") -> 0 | K26: =IF(5<=NW,IF(AND(ADV_CAP>0,C26>0,E26>ADV_CAP*C26),"⚠️ السلف فوق السقف",IF(G26<0,"⚠️ السلف أكثر من المستحق","")),"")
A27: =IF(6<=NW,"الأسبوع السادس","") -> الأسبوع السادس | B27: =IF(6<=NW,N('ساعات عمر'!E64),"") -> 0 | C27: =IF(6<=NW,N('ساعات عمر'!H65),"") -> 0 | D27: =IF(6<=NW,0,"") -> 0 | E27: =IF(6<=NW,SUMIFS(ADV_AMT,ADV_E,"عمر المصري",ADV_D,">="&القوائم!$H$16,ADV_D,"<="&القوائم!$I$16),"") -> 0 | F27: =IF(6<=NW,IF(N(C27)=0,0,MAX(0,MIN(IF(_xlfn.MAXIFS(LG_IDX,LG_E,"عمر المصري",LG_INST,"<>",LG_D,"<="&القوائم!$I$16)=0,$D$9,INDEX(LG_INST,_xlfn.MAXIFS(LG_IDX,LG_E,"عمر المصري",LG_INST,"<>",LG_D,"<="&القوائم!$I$16))),$C$9+SUMIFS(LG_DEBT,LG_E,"عمر المصري",LG_D,"<="&القوائم!$I$16)-SUMIFS(LG_REP,LG_E,"عمر المصري",LG_D,"<="&القوائم!$I$16)-SUM(F22:F26),N(C27)+N(D27)-N(E27)))),"") -> 0 | G27: =IF(6<=NW,C27+D27-E27-F27,"") -> 0 | I27: =IF(6<=NW,G27-N(H27),"") -> 0 | J27: =IF(6<=NW,MAX(0,$C$9+SUMIFS(LG_DEBT,LG_E,"عمر المصري",LG_D,"<="&القوائم!$I$16)-SUMIFS(LG_REP,LG_E,"عمر المصري",LG_D,"<="&القوائم!$I$16)-SUM(F22:F27)),"") -> 0 | K27: =IF(6<=NW,IF(AND(ADV_CAP>0,C27>0,E27>ADV_CAP*C27),"⚠️ السلف فوق السقف",IF(G27<0,"⚠️ السلف أكثر من المستحق","")),"")
A28: مجموع الشهر | B28: =SUM(B22:B27) -> 0 | C28: =SUM(C22:C27) -> 0 | D28: =SUM(D22:D27) -> 0 | E28: =SUM(E22:E27) -> 0 | F28: =SUM(F22:F27) -> 0 | G28: =SUM(G22:G27) -> 0 | H28: =SUM(H22:H27) -> 0 | I28: =SUM(I22:I27) -> 0 | J28: =MAX(0,$C$9+SUMIFS(LG_DEBT,LG_E,"عمر المصري")-SUMIFS(LG_REP,LG_E,"عمر المصري")-F28) -> 0
A30: عبدالعزيز — كل أسابيع الشهر
A31: الأسبوع | B31: عدد الساعات | C31: المستحق (دينار) | D31: + مدوّر | E31: − مقبوض يومياً | F31: − السلف | G31: − القسط | H31: الصافي للدفع | I31: المدفوع (دينار) | J31: الباقي له | K31: الدين المتبقي
A32: =IF(1<=NW,"الأسبوع الأول","") -> الأسبوع الأول | B32: =IF(1<=NW,N('ساعات عبدالعزيز'!E14),"") -> 0 | C32: =IF(1<=NW,N('ساعات عبدالعزيز'!F15),"") -> 0 | D32: =IF(1<=NW,$B$10,"") -> 0 | E32: =IF(1<=NW,N('ساعات عبدالعزيز'!H14),"") -> 0 | F32: =IF(1<=NW,SUMIFS(ADV_AMT,ADV_E,"عبدالعزيز",ADV_D,">="&القوائم!$H$11,ADV_D,"<="&القوائم!$I$11),"") -> 0 | G32: =IF(1<=NW,IF(N(C32)=0,0,MAX(0,MIN(IF(_xlfn.MAXIFS(LG_IDX,LG_E,"عبدالعزيز",LG_INST,"<>",LG_D,"<="&القوائم!$I$11)=0,$D$10,INDEX(LG_INST,_xlfn.MAXIFS(LG_IDX,LG_E,"عبدالعزيز",LG_INST,"<>",LG_D,"<="&القوائم!$I$11))),$C$10+SUMIFS(LG_DEBT,LG_E,"عبدالعزيز",LG_D,"<="&القوائم!$I$11)-SUMIFS(LG_REP,LG_E,"عبدالعزيز",LG_D,"<="&القوائم!$I$11)-0,N(C32)+N(D32)-N(E32)-N(F32)))),"") -> 0 | H32: =IF(1<=NW,C32+D32-E32-F32-G32,"") -> 0 | J32: =IF(1<=NW,H32-N(I32),"") -> 0 | K32: =IF(1<=NW,MAX(0,$C$10+SUMIFS(LG_DEBT,LG_E,"عبدالعزيز",LG_D,"<="&القوائم!$I$11)-SUMIFS(LG_REP,LG_E,"عبدالعزيز",LG_D,"<="&القوائم!$I$11)-SUM(G32:G32)),"") -> 0
A33: =IF(2<=NW,"الأسبوع الثاني","") -> الأسبوع الثاني | B33: =IF(2<=NW,N('ساعات عبدالعزيز'!E24),"") -> 0 | C33: =IF(2<=NW,N('ساعات عبدالعزيز'!F25),"") -> 0 | D33: =IF(2<=NW,0,"") -> 0 | E33: =IF(2<=NW,N('ساعات عبدالعزيز'!H24),"") -> 0 | F33: =IF(2<=NW,SUMIFS(ADV_AMT,ADV_E,"عبدالعزيز",ADV_D,">="&القوائم!$H$12,ADV_D,"<="&القوائم!$I$12),"") -> 0 | G33: =IF(2<=NW,IF(N(C33)=0,0,MAX(0,MIN(IF(_xlfn.MAXIFS(LG_IDX,LG_E,"عبدالعزيز",LG_INST,"<>",LG_D,"<="&القوائم!$I$12)=0,$D$10,INDEX(LG_INST,_xlfn.MAXIFS(LG_IDX,LG_E,"عبدالعزيز",LG_INST,"<>",LG_D,"<="&القوائم!$I$12))),$C$10+SUMIFS(LG_DEBT,LG_E,"عبدالعزيز",LG_D,"<="&القوائم!$I$12)-SUMIFS(LG_REP,LG_E,"عبدالعزيز",LG_D,"<="&القوائم!$I$12)-SUM(G32:G32),N(C33)+N(D33)-N(E33)-N(F33)))),"") -> 0 | H33: =IF(2<=NW,C33+D33-E33-F33-G33,"") -> 0 | J33: =IF(2<=NW,H33-N(I33),"") -> 0 | K33: =IF(2<=NW,MAX(0,$C$10+SUMIFS(LG_DEBT,LG_E,"عبدالعزيز",LG_D,"<="&القوائم!$I$12)-SUMIFS(LG_REP,LG_E,"عبدالعزيز",LG_D,"<="&القوائم!$I$12)-SUM(G32:G33)),"") -> 0
A34: =IF(3<=NW,"الأسبوع الثالث","") -> الأسبوع الثالث | B34: =IF(3<=NW,N('ساعات عبدالعزيز'!E34),"") -> 0 | C34: =IF(3<=NW,N('ساعات عبدالعزيز'!F35),"") -> 0 | D34: =IF(3<=NW,0,"") -> 0 | E34: =IF(3<=NW,N('ساعات عبدالعزيز'!H34),"") -> 0 | F34: =IF(3<=NW,SUMIFS(ADV_AMT,ADV_E,"عبدالعزيز",ADV_D,">="&القوائم!$H$13,ADV_D,"<="&القوائم!$I$13),"") -> 0 | G34: =IF(3<=NW,IF(N(C34)=0,0,MAX(0,MIN(IF(_xlfn.MAXIFS(LG_IDX,LG_E,"عبدالعزيز",LG_INST,"<>",LG_D,"<="&القوائم!$I$13)=0,$D$10,INDEX(LG_INST,_xlfn.MAXIFS(LG_IDX,LG_E,"عبدالعزيز",LG_INST,"<>",LG_D,"<="&القوائم!$I$13))),$C$10+SUMIFS(LG_DEBT,LG_E,"عبدالعزيز",LG_D,"<="&القوائم!$I$13)-SUMIFS(LG_REP,LG_E,"عبدالعزيز",LG_D,"<="&القوائم!$I$13)-SUM(G32:G33),N(C34)+N(D34)-N(E34)-N(F34)))),"") -> 0 | H34: =IF(3<=NW,C34+D34-E34-F34-G34,"") -> 0 | J34: =IF(3<=NW,H34-N(I34),"") -> 0 | K34: =IF(3<=NW,MAX(0,$C$10+SUMIFS(LG_DEBT,LG_E,"عبدالعزيز",LG_D,"<="&القوائم!$I$13)-SUMIFS(LG_REP,LG_E,"عبدالعزيز",LG_D,"<="&القوائم!$I$13)-SUM(G32:G34)),"") -> 0
A35: =IF(4<=NW,"الأسبوع الرابع","") -> الأسبوع الرابع | B35: =IF(4<=NW,N('ساعات عبدالعزيز'!E44),"") -> 0 | C35: =IF(4<=NW,N('ساعات عبدالعزيز'!F45),"") -> 0 | D35: =IF(4<=NW,0,"") -> 0 | E35: =IF(4<=NW,N('ساعات عبدالعزيز'!H44),"") -> 0 | F35: =IF(4<=NW,SUMIFS(ADV_AMT,ADV_E,"عبدالعزيز",ADV_D,">="&القوائم!$H$14,ADV_D,"<="&القوائم!$I$14),"") -> 0 | G35: =IF(4<=NW,IF(N(C35)=0,0,MAX(0,MIN(IF(_xlfn.MAXIFS(LG_IDX,LG_E,"عبدالعزيز",LG_INST,"<>",LG_D,"<="&القوائم!$I$14)=0,$D$10,INDEX(LG_INST,_xlfn.MAXIFS(LG_IDX,LG_E,"عبدالعزيز",LG_INST,"<>",LG_D,"<="&القوائم!$I$14))),$C$10+SUMIFS(LG_DEBT,LG_E,"عبدالعزيز",LG_D,"<="&القوائم!$I$14)-SUMIFS(LG_REP,LG_E,"عبدالعزيز",LG_D,"<="&القوائم!$I$14)-SUM(G32:G34),N(C35)+N(D35)-N(E35)-N(F35)))),"") -> 0 | H35: =IF(4<=NW,C35+D35-E35-F35-G35,"") -> 0 | J35: =IF(4<=NW,H35-N(I35),"") -> 0 | K35: =IF(4<=NW,MAX(0,$C$10+SUMIFS(LG_DEBT,LG_E,"عبدالعزيز",LG_D,"<="&القوائم!$I$14)-SUMIFS(LG_REP,LG_E,"عبدالعزيز",LG_D,"<="&القوائم!$I$14)-SUM(G32:G35)),"") -> 0
A36: =IF(5<=NW,"الأسبوع الخامس","") -> الأسبوع الخامس | B36: =IF(5<=NW,N('ساعات عبدالعزيز'!E54),"") -> 0 | C36: =IF(5<=NW,N('ساعات عبدالعزيز'!F55),"") -> 0 | D36: =IF(5<=NW,0,"") -> 0 | E36: =IF(5<=NW,N('ساعات عبدالعزيز'!H54),"") -> 0 | F36: =IF(5<=NW,SUMIFS(ADV_AMT,ADV_E,"عبدالعزيز",ADV_D,">="&القوائم!$H$15,ADV_D,"<="&القوائم!$I$15),"") -> 0 | G36: =IF(5<=NW,IF(N(C36)=0,0,MAX(0,MIN(IF(_xlfn.MAXIFS(LG_IDX,LG_E,"عبدالعزيز",LG_INST,"<>",LG_D,"<="&القوائم!$I$15)=0,$D$10,INDEX(LG_INST,_xlfn.MAXIFS(LG_IDX,LG_E,"عبدالعزيز",LG_INST,"<>",LG_D,"<="&القوائم!$I$15))),$C$10+SUMIFS(LG_DEBT,LG_E,"عبدالعزيز",LG_D,"<="&القوائم!$I$15)-SUMIFS(LG_REP,LG_E,"عبدالعزيز",LG_D,"<="&القوائم!$I$15)-SUM(G32:G35),N(C36)+N(D36)-N(E36)-N(F36)))),"") -> 0 | H36: =IF(5<=NW,C36+D36-E36-F36-G36,"") -> 0 | J36: =IF(5<=NW,H36-N(I36),"") -> 0 | K36: =IF(5<=NW,MAX(0,$C$10+SUMIFS(LG_DEBT,LG_E,"عبدالعزيز",LG_D,"<="&القوائم!$I$15)-SUMIFS(LG_REP,LG_E,"عبدالعزيز",LG_D,"<="&القوائم!$I$15)-SUM(G32:G36)),"") -> 0
A37: =IF(6<=NW,"الأسبوع السادس","") -> الأسبوع السادس | B37: =IF(6<=NW,N('ساعات عبدالعزيز'!E64),"") -> 0 | C37: =IF(6<=NW,N('ساعات عبدالعزيز'!F65),"") -> 0 | D37: =IF(6<=NW,0,"") -> 0 | E37: =IF(6<=NW,N('ساعات عبدالعزيز'!H64),"") -> 0 | F37: =IF(6<=NW,SUMIFS(ADV_AMT,ADV_E,"عبدالعزيز",ADV_D,">="&القوائم!$H$16,ADV_D,"<="&القوائم!$I$16),"") -> 0 | G37: =IF(6<=NW,IF(N(C37)=0,0,MAX(0,MIN(IF(_xlfn.MAXIFS(LG_IDX,LG_E,"عبدالعزيز",LG_INST,"<>",LG_D,"<="&القوائم!$I$16)=0,$D$10,INDEX(LG_INST,_xlfn.MAXIFS(LG_IDX,LG_E,"عبدالعزيز",LG_INST,"<>",LG_D,"<="&القوائم!$I$16))),$C$10+SUMIFS(LG_DEBT,LG_E,"عبدالعزيز",LG_D,"<="&القوائم!$I$16)-SUMIFS(LG_REP,LG_E,"عبدالعزيز",LG_D,"<="&القوائم!$I$16)-SUM(G32:G36),N(C37)+N(D37)-N(E37)-N(F37)))),"") -> 0 | H37: =IF(6<=NW,C37+D37-E37-F37-G37,"") -> 0 | J37: =IF(6<=NW,H37-N(I37),"") -> 0 | K37: =IF(6<=NW,MAX(0,$C$10+SUMIFS(LG_DEBT,LG_E,"عبدالعزيز",LG_D,"<="&القوائم!$I$16)-SUMIFS(LG_REP,LG_E,"عبدالعزيز",LG_D,"<="&القوائم!$I$16)-SUM(G32:G37)),"") -> 0
A38: مجموع الشهر | B38: =SUM(B32:B37) -> 0 | C38: =SUM(C32:C37) -> 0 | D38: =SUM(D32:D37) -> 0 | E38: =SUM(E32:E37) -> 0 | F38: =SUM(F32:F37) -> 0 | G38: =SUM(G32:G37) -> 0 | H38: =SUM(H32:H37) -> 0 | I38: =SUM(I32:I37) -> 0 | J38: =SUM(J32:J37) -> 0 | K38: =MAX(0,$C$10+SUMIFS(LG_DEBT,LG_E,"عبدالعزيز")-SUMIFS(LG_REP,LG_E,"عبدالعزيز")-G38) -> 0
A41: إقفال الشهر — هالأرقام بتنكتب بـ«افتتاح الشهر» بملف الشهر الجاي
A42: الموظف | B42: مستحق له لسا ما قبضه (دينار) | C42: قرض أو دين متبقي عليه (دينار) | D42: القسط الأسبوعي (دينار)
A43: عمر المصري | B43: =I28 -> 0 | C43: =$C$9+SUMIFS(LG_DEBT,LG_E,A43)-SUMIFS(LG_REP,LG_E,A43)-F28 -> 0 | D43: =IF(C43>0,IF(_xlfn.MAXIFS(LG_IDX,LG_E,"عمر المصري",LG_INST,"<>",LG_D,"<="&MEND)=0,$D$9,INDEX(LG_INST,_xlfn.MAXIFS(LG_IDX,LG_E,"عمر المصري",LG_INST,"<>",LG_D,"<="&MEND))),0) -> 0 | E43: =IF(B43>0.0005,"المحل لسا مدين إله بـ "&TEXT(B43,"0.000"),IF(B43<-0.0005,"قبض زيادة "&TEXT(-B43,"0.000")&" — بتنخصم الشهر الجاي","ما إله شي"))&IF(C43>0.0005," · وعليه دين "&TEXT(C43,"0.000"),"") -> ما إله شي
A44: عبدالعزيز | B44: =J38 -> 0 | C44: =$C$10+SUMIFS(LG_DEBT,LG_E,A44)-SUMIFS(LG_REP,LG_E,A44)-G38 -> 0 | D44: =IF(C44>0,IF(_xlfn.MAXIFS(LG_IDX,LG_E,"عبدالعزيز",LG_INST,"<>",LG_D,"<="&MEND)=0,$D$10,INDEX(LG_INST,_xlfn.MAXIFS(LG_IDX,LG_E,"عبدالعزيز",LG_INST,"<>",LG_D,"<="&MEND))),0) -> 0 | E44: =IF(B44>0.0005,"المحل لسا مدين إله بـ "&TEXT(B44,"0.000"),IF(B44<-0.0005,"قبض زيادة "&TEXT(-B44,"0.000")&" — بتنخصم الشهر الجاي","ما إله شي"))&IF(C44>0.0005," · وعليه دين "&TEXT(C44,"0.000"),"") -> ما إله شي

Sheet ساعات عمر
A1: ساعات عمر المصري
A2: ="شهر "&TEXT(التسوية!$C$3,"00")&" / "&التسوية!$E$3&" (الشهر والسنة بتنختار من ورقة التسوية)" -> شهر 10 / 2026 (الشهر والسنة بتنختار من ورقة التسوية)
A3: اختر الدخول والخروج (AM/PM) — عدد الساعات والعادي والإضافي والمستحق بيطلعوا لحالهم. السبت–الخميس: بعد 6:00 PM إضافي @1.500 · الجمعة كل الساعات @1.250. ساعات تحميل الجبسمبورد بتنكتب مرة وحدة تحت كل أسبوع. مستحق الأسبوع بيتجبر لربع دينار.
A5: التاريخ | B5: اليوم | C5: دخول | D5: خروج | E5: عدد الساعات | F5: منها عادي | G5: منها إضافي | H5: المستحق (دينار) | I5: ملاحظات
A6: =IF(1<=NW,"الأسبوع الأول","") -> الأسبوع الأول
A7: =IF(AND(1<=NW,WFIRST+0>=MSTART,WFIRST+0<=MEND),WFIRST+0,"") | B7: =IF(A7="","",CHOOSE(WEEKDAY(A7,1),"الأحد","الاثنين","الثلاثاء","الأربعاء","الخميس","الجمعة","السبت")) | E7: =IF(OR(M7=0,K7="",L7=""),"",MOD(L7-K7,1)) | F7: =IF(OR(E7="",M7=0),"",IF(WEEKDAY(A7,1)=6,E7,MIN(E7,MAX(0,MIN(IF(L7<K7,L7+1,L7),OMR_OT_AT)-K7)))) | G7: =IF(OR(E7="",M7=0),"",MAX(0,E7-F7)) | H7: =IF(OR(E7="",M7=0),"",ROUND((F7*OMR_RATE+G7*OMR_OT)*24,3)) | K7: =IF(OR(M7=0,C7=""),"",IF(ISNUMBER(C7),MOD(C7,1),IFERROR(INDEX(القوائم!$B$1:$B$96,MATCH(TRIM(C7),القوائم!$A$1:$A$96,0)),IFERROR(MOD(TIMEVALUE(C7),1),"")))) | L7: =IF(OR(M7=0,D7=""),"",IF(ISNUMBER(D7),MOD(D7,1),IFERROR(INDEX(القوائم!$B$1:$B$96,MATCH(TRIM(D7),القوائم!$A$1:$A$96,0)),IFERROR(MOD(TIMEVALUE(D7),1),"")))) | M7: =IF(A7="",0,IF(AND(A7>=MSTART,A7<=MEND),1,0)) -> 0
A8: =IF(AND(1<=NW,WFIRST+1>=MSTART,WFIRST+1<=MEND),WFIRST+1,"") | B8: =IF(A8="","",CHOOSE(WEEKDAY(A8,1),"الأحد","الاثنين","الثلاثاء","الأربعاء","الخميس","الجمعة","السبت")) | E8: =IF(OR(M8=0,K8="",L8=""),"",MOD(L8-K8,1)) | F8: =IF(OR(E8="",M8=0),"",IF(WEEKDAY(A8,1)=6,E8,MIN(E8,MAX(0,MIN(IF(L8<K8,L8+1,L8),OMR_OT_AT)-K8)))) | G8: =IF(OR(E8="",M8=0),"",MAX(0,E8-F8)) | H8: =IF(OR(E8="",M8=0),"",ROUND((F8*OMR_RATE+G8*OMR_OT)*24,3)) | K8: =IF(OR(M8=0,C8=""),"",IF(ISNUMBER(C8),MOD(C8,1),IFERROR(INDEX(القوائم!$B$1:$B$96,MATCH(TRIM(C8),القوائم!$A$1:$A$96,0)),IFERROR(MOD(TIMEVALUE(C8),1),"")))) | L8: =IF(OR(M8=0,D8=""),"",IF(ISNUMBER(D8),MOD(D8,1),IFERROR(INDEX(القوائم!$B$1:$B$96,MATCH(TRIM(D8),القوائم!$A$1:$A$96,0)),IFERROR(MOD(TIMEVALUE(D8),1),"")))) | M8: =IF(A8="",0,IF(AND(A8>=MSTART,A8<=MEND),1,0)) -> 0
A9: =IF(AND(1<=NW,WFIRST+2>=MSTART,WFIRST+2<=MEND),WFIRST+2,"") | B9: =IF(A9="","",CHOOSE(WEEKDAY(A9,1),"الأحد","الاثنين","الثلاثاء","الأربعاء","الخميس","الجمعة","السبت")) | E9: =IF(OR(M9=0,K9="",L9=""),"",MOD(L9-K9,1)) | F9: =IF(OR(E9="",M9=0),"",IF(WEEKDAY(A9,1)=6,E9,MIN(E9,MAX(0,MIN(IF(L9<K9,L9+1,L9),OMR_OT_AT)-K9)))) | G9: =IF(OR(E9="",M9=0),"",MAX(0,E9-F9)) | H9: =IF(OR(E9="",M9=0),"",ROUND((F9*OMR_RATE+G9*OMR_OT)*24,3)) | K9: =IF(OR(M9=0,C9=""),"",IF(ISNUMBER(C9),MOD(C9,1),IFERROR(INDEX(القوائم!$B$1:$B$96,MATCH(TRIM(C9),القوائم!$A$1:$A$96,0)),IFERROR(MOD(TIMEVALUE(C9),1),"")))) | L9: =IF(OR(M9=0,D9=""),"",IF(ISNUMBER(D9),MOD(D9,1),IFERROR(INDEX(القوائم!$B$1:$B$96,MATCH(TRIM(D9),القوائم!$A$1:$A$96,0)),IFERROR(MOD(TIMEVALUE(D9),1),"")))) | M9: =IF(A9="",0,IF(AND(A9>=MSTART,A9<=MEND),1,0)) -> 0
A10: =IF(AND(1<=NW,WFIRST+3>=MSTART,WFIRST+3<=MEND),WFIRST+3,"") | B10: =IF(A10="","",CHOOSE(WEEKDAY(A10,1),"الأحد","الاثنين","الثلاثاء","الأربعاء","الخميس","الجمعة","السبت")) | E10: =IF(OR(M10=0,K10="",L10=""),"",MOD(L10-K10,1)) | F10: =IF(OR(E10="",M10=0),"",IF(WEEKDAY(A10,1)=6,E10,MIN(E10,MAX(0,MIN(IF(L10<K10,L10+1,L10),OMR_OT_AT)-K10)))) | G10: =IF(OR(E10="",M10=0),"",MAX(0,E10-F10)) | H10: =IF(OR(E10="",M10=0),"",ROUND((F10*OMR_RATE+G10*OMR_OT)*24,3)) | K10: =IF(OR(M10=0,C10=""),"",IF(ISNUMBER(C10),MOD(C10,1),IFERROR(INDEX(القوائم!$B$1:$B$96,MATCH(TRIM(C10),القوائم!$A$1:$A$96,0)),IFERROR(MOD(TIMEVALUE(C10),1),"")))) | L10: =IF(OR(M10=0,D10=""),"",IF(ISNUMBER(D10),MOD(D10,1),IFERROR(INDEX(القوائم!$B$1:$B$96,MATCH(TRIM(D10),القوائم!$A$1:$A$96,0)),IFERROR(MOD(TIMEVALUE(D10),1),"")))) | M10: =IF(A10="",0,IF(AND(A10>=MSTART,A10<=MEND),1,0)) -> 0
A11: =IF(AND(1<=NW,WFIRST+4>=MSTART,WFIRST+4<=MEND),WFIRST+4,"") | B11: =IF(A11="","",CHOOSE(WEEKDAY(A11,1),"الأحد","الاثنين","الثلاثاء","الأربعاء","الخميس","الجمعة","السبت")) | E11: =IF(OR(M11=0,K11="",L11=""),"",MOD(L11-K11,1)) | F11: =IF(OR(E11="",M11=0),"",IF(WEEKDAY(A11,1)=6,E11,MIN(E11,MAX(0,MIN(IF(L11<K11,L11+1,L11),OMR_OT_AT)-K11)))) | G11: =IF(OR(E11="",M11=0),"",MAX(0,E11-F11)) | H11: =IF(OR(E11="",M11=0),"",ROUND((F11*OMR_RATE+G11*OMR_OT)*24,3)) | K11: =IF(OR(M11=0,C11=""),"",IF(ISNUMBER(C11),MOD(C11,1),IFERROR(INDEX(القوائم!$B$1:$B$96,MATCH(TRIM(C11),القوائم!$A$1:$A$96,0)),IFERROR(MOD(TIMEVALUE(C11),1),"")))) | L11: =IF(OR(M11=0,D11=""),"",IF(ISNUMBER(D11),MOD(D11,1),IFERROR(INDEX(القوائم!$B$1:$B$96,MATCH(TRIM(D11),القوائم!$A$1:$A$96,0)),IFERROR(MOD(TIMEVALUE(D11),1),"")))) | M11: =IF(A11="",0,IF(AND(A11>=MSTART,A11<=MEND),1,0)) -> 0
A12: =IF(AND(1<=NW,WFIRST+5>=MSTART,WFIRST+5<=MEND),WFIRST+5,"") -> 46296 | B12: =IF(A12="","",CHOOSE(WEEKDAY(A12,1),"الأحد","الاثنين","الثلاثاء","الأربعاء","الخميس","الجمعة","السبت")) -> الخميس | E12: =IF(OR(M12=0,K12="",L12=""),"",MOD(L12-K12,1)) | F12: =IF(OR(E12="",M12=0),"",IF(WEEKDAY(A12,1)=6,E12,MIN(E12,MAX(0,MIN(IF(L12<K12,L12+1,L12),OMR_OT_AT)-K12)))) | G12: =IF(OR(E12="",M12=0),"",MAX(0,E12-F12)) | H12: =IF(OR(E12="",M12=0),"",ROUND((F12*OMR_RATE+G12*OMR_OT)*24,3)) | K12: =IF(OR(M12=0,C12=""),"",IF(ISNUMBER(C12),MOD(C12,1),IFERROR(INDEX(القوائم!$B$1:$B$96,MATCH(TRIM(C12),القوائم!$A$1:$A$96,0)),IFERROR(MOD(TIMEVALUE(C12),1),"")))) | L12: =IF(OR(M12=0,D12=""),"",IF(ISNUMBER(D12),MOD(D12,1),IFERROR(INDEX(القوائم!$B$1:$B$96,MATCH(TRIM(D12),القوائم!$A$1:$A$96,0)),IFERROR(MOD(TIMEVALUE(D12),1),"")))) | M12: =IF(A12="",0,IF(AND(A12>=MSTART,A12<=MEND),1,0)) -> 1
A13: =IF(AND(1<=NW,WFIRST+6>=MSTART,WFIRST+6<=MEND),WFIRST+6,"") -> 46297 | B13: =IF(A13="","",CHOOSE(WEEKDAY(A13,1),"الأحد","الاثنين","الثلاثاء","الأربعاء","الخميس","الجمعة","السبت")) -> الجمعة | E13: =IF(OR(M13=0,K13="",L13=""),"",MOD(L13-K13,1)) | F13: =IF(OR(E13="",M13=0),"",IF(WEEKDAY(A13,1)=6,E13,MIN(E13,MAX(0,MIN(IF(L13<K13,L13+1,L13),OMR_OT_AT)-K13)))) | G13: =IF(OR(E13="",M13=0),"",MAX(0,E13-F13)) | H13: =IF(OR(E13="",M13=0),"",ROUND((F13*OMR_RATE+G13*OMR_OT)*24,3)) | K13: =IF(OR(M13=0,C13=""),"",IF(ISNUMBER(C13),MOD(C13,1),IFERROR(INDEX(القوائم!$B$1:$B$96,MATCH(TRIM(C13),القوائم!$A$1:$A$96,0)),IFERROR(MOD(TIMEVALUE(C13),1),"")))) | L13: =IF(OR(M13=0,D13=""),"",IF(ISNUMBER(D13),MOD(D13,1),IFERROR(INDEX(القوائم!$B$1:$B$96,MATCH(TRIM(D13),القوائم!$A$1:$A$96,0)),IFERROR(MOD(TIMEVALUE(D13),1),"")))) | M13: =IF(A13="",0,IF(AND(A13>=MSTART,A13<=MEND),1,0)) -> 1
A14: =IF(1<=NW,"مجموع أيام الأسبوع الأول","") -> مجموع أيام الأسبوع الأول | E14: =IF(1<=NW,SUM(E7:E13),"") -> 0 | F14: =IF(1<=NW,SUM(F7:F13),"") -> 0 | G14: =IF(1<=NW,SUM(G7:G13),"") -> 0 | H14: =IF(1<=NW,SUM(H7:H13),"") -> 0
A15: =IF(1<=NW,"ساعات تحميل الجبسمبورد بهالأسبوع (رقم: 2 أو 1.5) ←","") -> ساعات تحميل الجبسمبورد بهالأسبوع (رقم: 2 أو 1.5) ← | F15: =IF(1<=NW,"المستحق النهائي للأسبوع (دينار) ←","") -> المستحق النهائي للأسبوع (دينار) ← | H15: =IF(1<=NW,IF(ROUND_MODE="للأعلى",CEILING(ROUND((N(H14)+N(E15)*(GYP_RATE-OMR_RATE)),3),0.25),ROUND((N(H14)+N(E15)*(GYP_RATE-OMR_RATE))*4,0)/4),"") -> 0 | I15: =IF(1<=NW,"قبل الجبر: "&TEXT(N(H14)+N(E15)*(GYP_RATE-OMR_RATE),"0.000"),"") -> قبل الجبر: 0.000
A16: =IF(2<=NW,"الأسبوع الثاني","") -> الأسبوع الثاني
A17: =IF(AND(2<=NW,WFIRST+7>=MSTART,WFIRST+7<=MEND),WFIRST+7,"") -> 46298 | B17: =IF(A17="","",CHOOSE(WEEKDAY(A17,1),"الأحد","الاثنين","الثلاثاء","الأربعاء","الخميس","الجمعة","السبت")) -> السبت | E17: =IF(OR(M17=0,K17="",L17=""),"",MOD(L17-K17,1)) | F17: =IF(OR(E17="",M17=0),"",IF(WEEKDAY(A17,1)=6,E17,MIN(E17,MAX(0,MIN(IF(L17<K17,L17+1,L17),OMR_OT_AT)-K17)))) | G17: =IF(OR(E17="",M17=0),"",MAX(0,E17-F17)) | H17: =IF(OR(E17="",M17=0),"",ROUND((F17*OMR_RATE+G17*OMR_OT)*24,3)) | K17: =IF(OR(M17=0,C17=""),"",IF(ISNUMBER(C17),MOD(C17,1),IFERROR(INDEX(القوائم!$B$1:$B$96,MATCH(TRIM(C17),القوائم!$A$1:$A$96,0)),IFERROR(MOD(TIMEVALUE(C17),1),"")))) | L17: =IF(OR(M17=0,D17=""),"",IF(ISNUMBER(D17),MOD(D17,1),IFERROR(INDEX(القوائم!$B$1:$B$96,MATCH(TRIM(D17),القوائم!$A$1:$A$96,0)),IFERROR(MOD(TIMEVALUE(D17),1),"")))) | M17: =IF(A17="",0,IF(AND(A17>=MSTART,A17<=MEND),1,0)) -> 1
A18: =IF(AND(2<=NW,WFIRST+8>=MSTART,WFIRST+8<=MEND),WFIRST+8,"") -> 46299 | B18: =IF(A18="","",CHOOSE(WEEKDAY(A18,1),"الأحد","الاثنين","الثلاثاء","الأربعاء","الخميس","الجمعة","السبت")) -> الأحد | E18: =IF(OR(M18=0,K18="",L18=""),"",MOD(L18-K18,1)) | F18: =IF(OR(E18="",M18=0),"",IF(WEEKDAY(A18,1)=6,E18,MIN(E18,MAX(0,MIN(IF(L18<K18,L18+1,L18),OMR_OT_AT)-K18)))) | G18: =IF(OR(E18="",M18=0),"",MAX(0,E18-F18)) | H18: =IF(OR(E18="",M18=0),"",ROUND((F18*OMR_RATE+G18*OMR_OT)*24,3)) | K18: =IF(OR(M18=0,C18=""),"",IF(ISNUMBER(C18),MOD(C18,1),IFERROR(INDEX(القوائم!$B$1:$B$96,MATCH(TRIM(C18),القوائم!$A$1:$A$96,0)),IFERROR(MOD(TIMEVALUE(C18),1),"")))) | L18: =IF(OR(M18=0,D18=""),"",IF(ISNUMBER(D18),MOD(D18,1),IFERROR(INDEX(القوائم!$B$1:$B$96,MATCH(TRIM(D18),القوائم!$A$1:$A$96,0)),IFERROR(MOD(TIMEVALUE(D18),1),"")))) | M18: =IF(A18="",0,IF(AND(A18>=MSTART,A18<=MEND),1,0)) -> 1
A19: =IF(AND(2<=NW,WFIRST+9>=MSTART,WFIRST+9<=MEND),WFIRST+9,"") -> 46300 | B19: =IF(A19="","",CHOOSE(WEEKDAY(A19,1),"الأحد","الاثنين","الثلاثاء","الأربعاء","الخميس","الجمعة","السبت")) -> الاثنين | E19: =IF(OR(M19=0,K19="",L19=""),"",MOD(L19-K19,1)) | F19: =IF(OR(E19="",M19=0),"",IF(WEEKDAY(A19,1)=6,E19,MIN(E19,MAX(0,MIN(IF(L19<K19,L19+1,L19),OMR_OT_AT)-K19)))) | G19: =IF(OR(E19="",M19=0),"",MAX(0,E19-F19)) | H19: =IF(OR(E19="",M19=0),"",ROUND((F19*OMR_RATE+G19*OMR_OT)*24,3)) | K19: =IF(OR(M19=0,C19=""),"",IF(ISNUMBER(C19),MOD(C19,1),IFERROR(INDEX(القوائم!$B$1:$B$96,MATCH(TRIM(C19),القوائم!$A$1:$A$96,0)),IFERROR(MOD(TIMEVALUE(C19),1),"")))) | L19: =IF(OR(M19=0,D19=""),"",IF(ISNUMBER(D19),MOD(D19,1),IFERROR(INDEX(القوائم!$B$1:$B$96,MATCH(TRIM(D19),القوائم!$A$1:$A$96,0)),IFERROR(MOD(TIMEVALUE(D19),1),"")))) | M19: =IF(A19="",0,IF(AND(A19>=MSTART,A19<=MEND),1,0)) -> 1
A20: =IF(AND(2<=NW,WFIRST+10>=MSTART,WFIRST+10<=MEND),WFIRST+10,"") -> 46301 | B20: =IF(A20="","",CHOOSE(WEEKDAY(A20,1),"الأحد","الاثنين","الثلاثاء","الأربعاء","الخميس","الجمعة","السبت")) -> الثلاثاء | E20: =IF(OR(M20=0,K20="",L20=""),"",MOD(L20-K20,1)) | F20: =IF(OR(E20="",M20=0),"",IF(WEEKDAY(A20,1)=6,E20,MIN(E20,MAX(0,MIN(IF(L20<K20,L20+1,L20),OMR_OT_AT)-K20)))) | G20: =IF(OR(E20="",M20=0),"",MAX(0,E20-F20)) | H20: =IF(OR(E20="",M20=0),"",ROUND((F20*OMR_RATE+G20*OMR_OT)*24,3)) | K20: =IF(OR(M20=0,C20=""),"",IF(ISNUMBER(C20),MOD(C20,1),IFERROR(INDEX(القوائم!$B$1:$B$96,MATCH(TRIM(C20),القوائم!$A$1:$A$96,0)),IFERROR(MOD(TIMEVALUE(C20),1),"")))) | L20: =IF(OR(M20=0,D20=""),"",IF(ISNUMBER(D20),MOD(D20,1),IFERROR(INDEX(القوائم!$B$1:$B$96,MATCH(TRIM(D20),القوائم!$A$1:$A$96,0)),IFERROR(MOD(TIMEVALUE(D20),1),"")))) | M20: =IF(A20="",0,IF(AND(A20>=MSTART,A20<=MEND),1,0)) -> 1
A21: =IF(AND(2<=NW,WFIRST+11>=MSTART,WFIRST+11<=MEND),WFIRST+11,"") -> 46302 | B21: =IF(A21="","",CHOOSE(WEEKDAY(A21,1),"الأحد","الاثنين","الثلاثاء","الأربعاء","الخميس","الجمعة","السبت")) -> الأربعاء | E21: =IF(OR(M21=0,K21="",L21=""),"",MOD(L21-K21,1)) | F21: =IF(OR(E21="",M21=0),"",IF(WEEKDAY(A21,1)=6,E21,MIN(E21,MAX(0,MIN(IF(L21<K21,L21+1,L21),OMR_OT_AT)-K21)))) | G21: =IF(OR(E21="",M21=0),"",MAX(0,E21-F21)) | H21: =IF(OR(E21="",M21=0),"",ROUND((F21*OMR_RATE+G21*OMR_OT)*24,3)) | K21: =IF(OR(M21=0,C21=""),"",IF(ISNUMBER(C21),MOD(C21,1),IFERROR(INDEX(القوائم!$B$1:$B$96,MATCH(TRIM(C21),القوائم!$A$1:$A$96,0)),IFERROR(MOD(TIMEVALUE(C21),1),"")))) | L21: =IF(OR(M21=0,D21=""),"",IF(ISNUMBER(D21),MOD(D21,1),IFERROR(INDEX(القوائم!$B$1:$B$96,MATCH(TRIM(D21),القوائم!$A$1:$A$96,0)),IFERROR(MOD(TIMEVALUE(D21),1),"")))) | M21: =IF(A21="",0,IF(AND(A21>=MSTART,A21<=MEND),1,0)) -> 1
A22: =IF(AND(2<=NW,WFIRST+12>=MSTART,WFIRST+12<=MEND),WFIRST+12,"") -> 46303 | B22: =IF(A22="","",CHOOSE(WEEKDAY(A22,1),"الأحد","الاثنين","الثلاثاء","الأربعاء","الخميس","الجمعة","السبت")) -> الخميس | E22: =IF(OR(M22=0,K22="",L22=""),"",MOD(L22-K22,1)) | F22: =IF(OR(E22="",M22=0),"",IF(WEEKDAY(A22,1)=6,E22,MIN(E22,MAX(0,MIN(IF(L22<K22,L22+1,L22),OMR_OT_AT)-K22)))) | G22: =IF(OR(E22="",M22=0),"",MAX(0,E22-F22)) | H22: =IF(OR(E22="",M22=0),"",ROUND((F22*OMR_RATE+G22*OMR_OT)*24,3)) | K22: =IF(OR(M22=0,C22=""),"",IF(ISNUMBER(C22),MOD(C22,1),IFERROR(INDEX(القوائم!$B$1:$B$96,MATCH(TRIM(C22),القوائم!$A$1:$A$96,0)),IFERROR(MOD(TIMEVALUE(C22),1),"")))) | L22: =IF(OR(M22=0,D22=""),"",IF(ISNUMBER(D22),MOD(D22,1),IFERROR(INDEX(القوائم!$B$1:$B$96,MATCH(TRIM(D22),القوائم!$A$1:$A$96,0)),IFERROR(MOD(TIMEVALUE(D22),1),"")))) | M22: =IF(A22="",0,IF(AND(A22>=MSTART,A22<=MEND),1,0)) -> 1
A23: =IF(AND(2<=NW,WFIRST+13>=MSTART,WFIRST+13<=MEND),WFIRST+13,"") -> 46304 | B23: =IF(A23="","",CHOOSE(WEEKDAY(A23,1),"الأحد","الاثنين","الثلاثاء","الأربعاء","الخميس","الجمعة","السبت")) -> الجمعة | E23: =IF(OR(M23=0,K23="",L23=""),"",MOD(L23-K23,1)) | F23: =IF(OR(E23="",M23=0),"",IF(WEEKDAY(A23,1)=6,E23,MIN(E23,MAX(0,MIN(IF(L23<K23,L23+1,L23),OMR_OT_AT)-K23)))) | G23: =IF(OR(E23="",M23=0),"",MAX(0,E23-F23)) | H23: =IF(OR(E23="",M23=0),"",ROUND((F23*OMR_RATE+G23*OMR_OT)*24,3)) | K23: =IF(OR(M23=0,C23=""),"",IF(ISNUMBER(C23),MOD(C23,1),IFERROR(INDEX(القوائم!$B$1:$B$96,MATCH(TRIM(C23),القوائم!$A$1:$A$96,0)),IFERROR(MOD(TIMEVALUE(C23),1),"")))) | L23: =IF(OR(M23=0,D23=""),"",IF(ISNUMBER(D23),MOD(D23,1),IFERROR(INDEX(القوائم!$B$1:$B$96,MATCH(TRIM(D23),القوائم!$A$1:$A$96,0)),IFERROR(MOD(TIMEVALUE(D23),1),"")))) | M23: =IF(A23="",0,IF(AND(A23>=MSTART,A23<=MEND),1,0)) -> 1
A24: =IF(2<=NW,"مجموع أيام الأسبوع الثاني","") -> مجموع أيام الأسبوع الثاني | E24: =IF(2<=NW,SUM(E17:E23),"") -> 0 | F24: =IF(2<=NW,SUM(F17:F23),"") -> 0 | G24: =IF(2<=NW,SUM(G17:G23),"") -> 0 | H24: =IF(2<=NW,SUM(H17:H23),"") -> 0
A25: =IF(2<=NW,"ساعات تحميل الجبسمبورد بهالأسبوع (رقم: 2 أو 1.5) ←","") -> ساعات تحميل الجبسمبورد بهالأسبوع (رقم: 2 أو 1.5) ← | F25: =IF(2<=NW,"المستحق النهائي للأسبوع (دينار) ←","") -> المستحق النهائي للأسبوع (دينار) ← | H25: =IF(2<=NW,IF(ROUND_MODE="للأعلى",CEILING(ROUND((N(H24)+N(E25)*(GYP_RATE-OMR_RATE)),3),0.25),ROUND((N(H24)+N(E25)*(GYP_RATE-OMR_RATE))*4,0)/4),"") -> 0 | I25: =IF(2<=NW,"قبل الجبر: "&TEXT(N(H24)+N(E25)*(GYP_RATE-OMR_RATE),"0.000"),"") -> قبل الجبر: 0.000
A26: =IF(3<=NW,"الأسبوع الثالث","") -> الأسبوع الثالث
A27: =IF(AND(3<=NW,WFIRST+14>=MSTART,WFIRST+14<=MEND),WFIRST+14,"") -> 46305 | B27: =IF(A27="","",CHOOSE(WEEKDAY(A27,1),"الأحد","الاثنين","الثلاثاء","الأربعاء","الخميس","الجمعة","السبت")) -> السبت | E27: =IF(OR(M27=0,K27="",L27=""),"",MOD(L27-K27,1)) | F27: =IF(OR(E27="",M27=0),"",IF(WEEKDAY(A27,1)=6,E27,MIN(E27,MAX(0,MIN(IF(L27<K27,L27+1,L27),OMR_OT_AT)-K27)))) | G27: =IF(OR(E27="",M27=0),"",MAX(0,E27-F27)) | H27: =IF(OR(E27="",M27=0),"",ROUND((F27*OMR_RATE+G27*OMR_OT)*24,3)) | K27: =IF(OR(M27=0,C27=""),"",IF(ISNUMBER(C27),MOD(C27,1),IFERROR(INDEX(القوائم!$B$1:$B$96,MATCH(TRIM(C27),القوائم!$A$1:$A$96,0)),IFERROR(MOD(TIMEVALUE(C27),1),"")))) | L27: =IF(OR(M27=0,D27=""),"",IF(ISNUMBER(D27),MOD(D27,1),IFERROR(INDEX(القوائم!$B$1:$B$96,MATCH(TRIM(D27),القوائم!$A$1:$A$96,0)),IFERROR(MOD(TIMEVALUE(D27),1),"")))) | M27: =IF(A27="",0,IF(AND(A27>=MSTART,A27<=MEND),1,0)) -> 1
A28: =IF(AND(3<=NW,WFIRST+15>=MSTART,WFIRST+15<=MEND),WFIRST+15,"") -> 46306 | B28: =IF(A28="","",CHOOSE(WEEKDAY(A28,1),"الأحد","الاثنين","الثلاثاء","الأربعاء","الخميس","الجمعة","السبت")) -> الأحد | E28: =IF(OR(M28=0,K28="",L28=""),"",MOD(L28-K28,1)) | F28: =IF(OR(E28="",M28=0),"",IF(WEEKDAY(A28,1)=6,E28,MIN(E28,MAX(0,MIN(IF(L28<K28,L28+1,L28),OMR_OT_AT)-K28)))) | G28: =IF(OR(E28="",M28=0),"",MAX(0,E28-F28)) | H28: =IF(OR(E28="",M28=0),"",ROUND((F28*OMR_RATE+G28*OMR_OT)*24,3)) | K28: =IF(OR(M28=0,C28=""),"",IF(ISNUMBER(C28),MOD(C28,1),IFERROR(INDEX(القوائم!$B$1:$B$96,MATCH(TRIM(C28),القوائم!$A$1:$A$96,0)),IFERROR(MOD(TIMEVALUE(C28),1),"")))) | L28: =IF(OR(M28=0,D28=""),"",IF(ISNUMBER(D28),MOD(D28,1),IFERROR(INDEX(القوائم!$B$1:$B$96,MATCH(TRIM(D28),القوائم!$A$1:$A$96,0)),IFERROR(MOD(TIMEVALUE(D28),1),"")))) | M28: =IF(A28="",0,IF(AND(A28>=MSTART,A28<=MEND),1,0)) -> 1
A29: =IF(AND(3<=NW,WFIRST+16>=MSTART,WFIRST+16<=MEND),WFIRST+16,"") -> 46307 | B29: =IF(A29="","",CHOOSE(WEEKDAY(A29,1),"الأحد","الاثنين","الثلاثاء","الأربعاء","الخميس","الجمعة","السبت")) -> الاثنين | E29: =IF(OR(M29=0,K29="",L29=""),"",MOD(L29-K29,1)) | F29: =IF(OR(E29="",M29=0),"",IF(WEEKDAY(A29,1)=6,E29,MIN(E29,MAX(0,MIN(IF(L29<K29,L29+1,L29),OMR_OT_AT)-K29)))) | G29: =IF(OR(E29="",M29=0),"",MAX(0,E29-F29)) | H29: =IF(OR(E29="",M29=0),"",ROUND((F29*OMR_RATE+G29*OMR_OT)*24,3)) | K29: =IF(OR(M29=0,C29=""),"",IF(ISNUMBER(C29),MOD(C29,1),IFERROR(INDEX(القوائم!$B$1:$B$96,MATCH(TRIM(C29),القوائم!$A$1:$A$96,0)),IFERROR(MOD(TIMEVALUE(C29),1),"")))) | L29: =IF(OR(M29=0,D29=""),"",IF(ISNUMBER(D29),MOD(D29,1),IFERROR(INDEX(القوائم!$B$1:$B$96,MATCH(TRIM(D29),القوائم!$A$1:$A$96,0)),IFERROR(MOD(TIMEVALUE(D29),1),"")))) | M29: =IF(A29="",0,IF(AND(A29>=MSTART,A29<=MEND),1,0)) -> 1
A30: =IF(AND(3<=NW,WFIRST+17>=MSTART,WFIRST+17<=MEND),WFIRST+17,"") -> 46308 | B30: =IF(A30="","",CHOOSE(WEEKDAY(A30,1),"الأحد","الاثنين","الثلاثاء","الأربعاء","الخميس","الجمعة","السبت")) -> الثلاثاء | E30: =IF(OR(M30=0,K30="",L30=""),"",MOD(L30-K30,1)) | F30: =IF(OR(E30="",M30=0),"",IF(WEEKDAY(A30,1)=6,E30,MIN(E30,MAX(0,MIN(IF(L30<K30,L30+1,L30),OMR_OT_AT)-K30)))) | G30: =IF(OR(E30="",M30=0),"",MAX(0,E30-F30)) | H30: =IF(OR(E30="",M30=0),"",ROUND((F30*OMR_RATE+G30*OMR_OT)*24,3)) | K30: =IF(OR(M30=0,C30=""),"",IF(ISNUMBER(C30),MOD(C30,1),IFERROR(INDEX(القوائم!$B$1:$B$96,MATCH(TRIM(C30),القوائم!$A$1:$A$96,0)),IFERROR(MOD(TIMEVALUE(C30),1),"")))) | L30: =IF(OR(M30=0,D30=""),"",IF(ISNUMBER(D30),MOD(D30,1),IFERROR(INDEX(القوائم!$B$1:$B$96,MATCH(TRIM(D30),القوائم!$A$1:$A$96,0)),IFERROR(MOD(TIMEVALUE(D30),1),"")))) | M30: =IF(A30="",0,IF(AND(A30>=MSTART,A30<=MEND),1,0)) -> 1
A31: =IF(AND(3<=NW,WFIRST+18>=MSTART,WFIRST+18<=MEND),WFIRST+18,"") -> 46309 | B31: =IF(A31="","",CHOOSE(WEEKDAY(A31,1),"الأحد","الاثنين","الثلاثاء","الأربعاء","الخميس","الجمعة","السبت")) -> الأربعاء | E31: =IF(OR(M31=0,K31="",L31=""),"",MOD(L31-K31,1)) | F31: =IF(OR(E31="",M31=0),"",IF(WEEKDAY(A31,1)=6,E31,MIN(E31,MAX(0,MIN(IF(L31<K31,L31+1,L31),OMR_OT_AT)-K31)))) | G31: =IF(OR(E31="",M31=0),"",MAX(0,E31-F31)) | H31: =IF(OR(E31="",M31=0),"",ROUND((F31*OMR_RATE+G31*OMR_OT)*24,3)) | K31: =IF(OR(M31=0,C31=""),"",IF(ISNUMBER(C31),MOD(C31,1),IFERROR(INDEX(القوائم!$B$1:$B$96,MATCH(TRIM(C31),القوائم!$A$1:$A$96,0)),IFERROR(MOD(TIMEVALUE(C31),1),"")))) | L31: =IF(OR(M31=0,D31=""),"",IF(ISNUMBER(D31),MOD(D31,1),IFERROR(INDEX(القوائم!$B$1:$B$96,MATCH(TRIM(D31),القوائم!$A$1:$A$96,0)),IFERROR(MOD(TIMEVALUE(D31),1),"")))) | M31: =IF(A31="",0,IF(AND(A31>=MSTART,A31<=MEND),1,0)) -> 1
A32: =IF(AND(3<=NW,WFIRST+19>=MSTART,WFIRST+19<=MEND),WFIRST+19,"") -> 46310 | B32: =IF(A32="","",CHOOSE(WEEKDAY(A32,1),"الأحد","الاثنين","الثلاثاء","الأربعاء","الخميس","الجمعة","السبت")) -> الخميس | E32: =IF(OR(M32=0,K32="",L32=""),"",MOD(L32-K32,1)) | F32: =IF(OR(E32="",M32=0),"",IF(WEEKDAY(A32,1)=6,E32,MIN(E32,MAX(0,MIN(IF(L32<K32,L32+1,L32),OMR_OT_AT)-K32)))) | G32: =IF(OR(E32="",M32=0),"",MAX(0,E32-F32)) | H32: =IF(OR(E32="",M32=0),"",ROUND((F32*OMR_RATE+G32*OMR_OT)*24,3)) | K32: =IF(OR(M32=0,C32=""),"",IF(ISNUMBER(C32),MOD(C32,1),IFERROR(INDEX(القوائم!$B$1:$B$96,MATCH(TRIM(C32),القوائم!$A$1:$A$96,0)),IFERROR(MOD(TIMEVALUE(C32),1),"")))) | L32: =IF(OR(M32=0,D32=""),"",IF(ISNUMBER(D32),MOD(D32,1),IFERROR(INDEX(القوائم!$B$1:$B$96,MATCH(TRIM(D32),القوائم!$A$1:$A$96,0)),IFERROR(MOD(TIMEVALUE(D32),1),"")))) | M32: =IF(A32="",0,IF(AND(A32>=MSTART,A32<=MEND),1,0)) -> 1
A33: =IF(AND(3<=NW,WFIRST+20>=MSTART,WFIRST+20<=MEND),WFIRST+20,"") -> 46311 | B33: =IF(A33="","",CHOOSE(WEEKDAY(A33,1),"الأحد","الاثنين","الثلاثاء","الأربعاء","الخميس","الجمعة","السبت")) -> الجمعة | E33: =IF(OR(M33=0,K33="",L33=""),"",MOD(L33-K33,1)) | F33: =IF(OR(E33="",M33=0),"",IF(WEEKDAY(A33,1)=6,E33,MIN(E33,MAX(0,MIN(IF(L33<K33,L33+1,L33),OMR_OT_AT)-K33)))) | G33: =IF(OR(E33="",M33=0),"",MAX(0,E33-F33)) | H33: =IF(OR(E33="",M33=0),"",ROUND((F33*OMR_RATE+G33*OMR_OT)*24,3)) | K33: =IF(OR(M33=0,C33=""),"",IF(ISNUMBER(C33),MOD(C33,1),IFERROR(INDEX(القوائم!$B$1:$B$96,MATCH(TRIM(C33),القوائم!$A$1:$A$96,0)),IFERROR(MOD(TIMEVALUE(C33),1),"")))) | L33: =IF(OR(M33=0,D33=""),"",IF(ISNUMBER(D33),MOD(D33,1),IFERROR(INDEX(القوائم!$B$1:$B$96,MATCH(TRIM(D33),القوائم!$A$1:$A$96,0)),IFERROR(MOD(TIMEVALUE(D33),1),"")))) | M33: =IF(A33="",0,IF(AND(A33>=MSTART,A33<=MEND),1,0)) -> 1
A34: =IF(3<=NW,"مجموع أيام الأسبوع الثالث","") -> مجموع أيام الأسبوع الثالث | E34: =IF(3<=NW,SUM(E27:E33),"") -> 0 | F34: =IF(3<=NW,SUM(F27:F33),"") -> 0 | G34: =IF(3<=NW,SUM(G27:G33),"") -> 0 | H34: =IF(3<=NW,SUM(H27:H33),"") -> 0
A35: =IF(3<=NW,"ساعات تحميل الجبسمبورد بهالأسبوع (رقم: 2 أو 1.5) ←","") -> ساعات تحميل الجبسمبورد بهالأسبوع (رقم: 2 أو 1.5) ← | F35: =IF(3<=NW,"المستحق النهائي للأسبوع (دينار) ←","") -> المستحق النهائي للأسبوع (دينار) ← | H35: =IF(3<=NW,IF(ROUND_MODE="للأعلى",CEILING(ROUND((N(H34)+N(E35)*(GYP_RATE-OMR_RATE)),3),0.25),ROUND((N(H34)+N(E35)*(GYP_RATE-OMR_RATE))*4,0)/4),"") -> 0 | I35: =IF(3<=NW,"قبل الجبر: "&TEXT(N(H34)+N(E35)*(GYP_RATE-OMR_RATE),"0.000"),"") -> قبل الجبر: 0.000
A36: =IF(4<=NW,"الأسبوع الرابع","") -> الأسبوع الرابع
A37: =IF(AND(4<=NW,WFIRST+21>=MSTART,WFIRST+21<=MEND),WFIRST+21,"") -> 46312 | B37: =IF(A37="","",CHOOSE(WEEKDAY(A37,1),"الأحد","الاثنين","الثلاثاء","الأربعاء","الخميس","الجمعة","السبت")) -> السبت | E37: =IF(OR(M37=0,K37="",L37=""),"",MOD(L37-K37,1)) | F37: =IF(OR(E37="",M37=0),"",IF(WEEKDAY(A37,1)=6,E37,MIN(E37,MAX(0,MIN(IF(L37<K37,L37+1,L37),OMR_OT_AT)-K37)))) | G37: =IF(OR(E37="",M37=0),"",MAX(0,E37-F37)) | H37: =IF(OR(E37="",M37=0),"",ROUND((F37*OMR_RATE+G37*OMR_OT)*24,3)) | K37: =IF(OR(M37=0,C37=""),"",IF(ISNUMBER(C37),MOD(C37,1),IFERROR(INDEX(القوائم!$B$1:$B$96,MATCH(TRIM(C37),القوائم!$A$1:$A$96,0)),IFERROR(MOD(TIMEVALUE(C37),1),"")))) | L37: =IF(OR(M37=0,D37=""),"",IF(ISNUMBER(D37),MOD(D37,1),IFERROR(INDEX(القوائم!$B$1:$B$96,MATCH(TRIM(D37),القوائم!$A$1:$A$96,0)),IFERROR(MOD(TIMEVALUE(D37),1),"")))) | M37: =IF(A37="",0,IF(AND(A37>=MSTART,A37<=MEND),1,0)) -> 1
A38: =IF(AND(4<=NW,WFIRST+22>=MSTART,WFIRST+22<=MEND),WFIRST+22,"") -> 46313 | B38: =IF(A38="","",CHOOSE(WEEKDAY(A38,1),"الأحد","الاثنين","الثلاثاء","الأربعاء","الخميس","الجمعة","السبت")) -> الأحد | E38: =IF(OR(M38=0,K38="",L38=""),"",MOD(L38-K38,1)) | F38: =IF(OR(E38="",M38=0),"",IF(WEEKDAY(A38,1)=6,E38,MIN(E38,MAX(0,MIN(IF(L38<K38,L38+1,L38),OMR_OT_AT)-K38)))) | G38: =IF(OR(E38="",M38=0),"",MAX(0,E38-F38)) | H38: =IF(OR(E38="",M38=0),"",ROUND((F38*OMR_RATE+G38*OMR_OT)*24,3)) | K38: =IF(OR(M38=0,C38=""),"",IF(ISNUMBER(C38),MOD(C38,1),IFERROR(INDEX(القوائم!$B$1:$B$96,MATCH(TRIM(C38),القوائم!$A$1:$A$96,0)),IFERROR(MOD(TIMEVALUE(C38),1),"")))) | L38: =IF(OR(M38=0,D38=""),"",IF(ISNUMBER(D38),MOD(D38,1),IFERROR(INDEX(القوائم!$B$1:$B$96,MATCH(TRIM(D38),القوائم!$A$1:$A$96,0)),IFERROR(MOD(TIMEVALUE(D38),1),"")))) | M38: =IF(A38="",0,IF(AND(A38>=MSTART,A38<=MEND),1,0)) -> 1
A39: =IF(AND(4<=NW,WFIRST+23>=MSTART,WFIRST+23<=MEND),WFIRST+23,"") -> 46314 | B39: =IF(A39="","",CHOOSE(WEEKDAY(A39,1),"الأحد","الاثنين","الثلاثاء","الأربعاء","الخميس","الجمعة","السبت")) -> الاثنين | E39: =IF(OR(M39=0,K39="",L39=""),"",MOD(L39-K39,1)) | F39: =IF(OR(E39="",M39=0),"",IF(WEEKDAY(A39,1)=6,E39,MIN(E39,MAX(0,MIN(IF(L39<K39,L39+1,L39),OMR_OT_AT)-K39)))) | G39: =IF(OR(E39="",M39=0),"",MAX(0,E39-F39)) | H39: =IF(OR(E39="",M39=0),"",ROUND((F39*OMR_RATE+G39*OMR_OT)*24,3)) | K39: =IF(OR(M39=0,C39=""),"",IF(ISNUMBER(C39),MOD(C39,1),IFERROR(INDEX(القوائم!$B$1:$B$96,MATCH(TRIM(C39),القوائم!$A$1:$A$96,0)),IFERROR(MOD(TIMEVALUE(C39),1),"")))) | L39: =IF(OR(M39=0,D39=""),"",IF(ISNUMBER(D39),MOD(D39,1),IFERROR(INDEX(القوائم!$B$1:$B$96,MATCH(TRIM(D39),القوائم!$A$1:$A$96,0)),IFERROR(MOD(TIMEVALUE(D39),1),"")))) | M39: =IF(A39="",0,IF(AND(A39>=MSTART,A39<=MEND),1,0)) -> 1
A40: =IF(AND(4<=NW,WFIRST+24>=MSTART,WFIRST+24<=MEND),WFIRST+24,"") -> 46315 | B40: =IF(A40="","",CHOOSE(WEEKDAY(A40,1),"الأحد","الاثنين","الثلاثاء","الأربعاء","الخميس","الجمعة","السبت")) -> الثلاثاء | E40: =IF(OR(M40=0,K40="",L40=""),"",MOD(L40-K40,1)) | F40: =IF(OR(E40="",M40=0),"",IF(WEEKDAY(A40,1)=6,E40,MIN(E40,MAX(0,MIN(IF(L40<K40,L40+1,L40),OMR_OT_AT)-K40)))) | G40: =IF(OR(E40="",M40=0),"",MAX(0,E40-F40)) | H40: =IF(OR(E40="",M40=0),"",ROUND((F40*OMR_RATE+G40*OMR_OT)*24,3)) | K40: =IF(OR(M40=0,C40=""),"",IF(ISNUMBER(C40),MOD(C40,1),IFERROR(INDEX(القوائم!$B$1:$B$96,MATCH(TRIM(C40),القوائم!$A$1:$A$96,0)),IFERROR(MOD(TIMEVALUE(C40),1),"")))) | L40: =IF(OR(M40=0,D40=""),"",IF(ISNUMBER(D40),MOD(D40,1),IFERROR(INDEX(القوائم!$B$1:$B$96,MATCH(TRIM(D40),القوائم!$A$1:$A$96,0)),IFERROR(MOD(TIMEVALUE(D40),1),"")))) | M40: =IF(A40="",0,IF(AND(A40>=MSTART,A40<=MEND),1,0)) -> 1
A41: =IF(AND(4<=NW,WFIRST+25>=MSTART,WFIRST+25<=MEND),WFIRST+25,"") -> 46316 | B41: =IF(A41="","",CHOOSE(WEEKDAY(A41,1),"الأحد","الاثنين","الثلاثاء","الأربعاء","الخميس","الجمعة","السبت")) -> الأربعاء | E41: =IF(OR(M41=0,K41="",L41=""),"",MOD(L41-K41,1)) | F41: =IF(OR(E41="",M41=0),"",IF(WEEKDAY(A41,1)=6,E41,MIN(E41,MAX(0,MIN(IF(L41<K41,L41+1,L41),OMR_OT_AT)-K41)))) | G41: =IF(OR(E41="",M41=0),"",MAX(0,E41-F41)) | H41: =IF(OR(E41="",M41=0),"",ROUND((F41*OMR_RATE+G41*OMR_OT)*24,3)) | K41: =IF(OR(M41=0,C41=""),"",IF(ISNUMBER(C41),MOD(C41,1),IFERROR(INDEX(القوائم!$B$1:$B$96,MATCH(TRIM(C41),القوائم!$A$1:$A$96,0)),IFERROR(MOD(TIMEVALUE(C41),1),"")))) | L41: =IF(OR(M41=0,D41=""),"",IF(ISNUMBER(D41),MOD(D41,1),IFERROR(INDEX(القوائم!$B$1:$B$96,MATCH(TRIM(D41),القوائم!$A$1:$A$96,0)),IFERROR(MOD(TIMEVALUE(D41),1),"")))) | M41: =IF(A41="",0,IF(AND(A41>=MSTART,A41<=MEND),1,0)) -> 1
...

Sheet ساعات عبدالعزيز
A1: ساعات عبدالعزيز — بيقبض نهاية كل يوم
A2: ="شهر "&TEXT(التسوية!$C$3,"00")&" / "&التسوية!$E$3&" (الشهر والسنة بتنختار من ورقة التسوية)" -> شهر 10 / 2026 (الشهر والسنة بتنختار من ورقة التسوية)
A3: دينار للساعة أي يوم. مستحق كل يوم مجبور لربع دينار. لما يقبض آخر اليوم: «نعم» + المبلغ. ساعات الجبسمبورد تحت كل أسبوع — فرقها بينضاف لمستحق الأسبوع وبيندفع آخره.
A5: التاريخ | B5: اليوم | C5: دخول | D5: خروج | E5: عدد الساعات | F5: مستحق اليوم (دينار) | G5: قبض؟ | H5: المقبوض (دينار) | I5: ملاحظات
A6: =IF(1<=NW,"الأسبوع الأول","") -> الأسبوع الأول
A7: =IF(AND(1<=NW,WFIRST+0>=MSTART,WFIRST+0<=MEND),WFIRST+0,"") | B7: =IF(A7="","",CHOOSE(WEEKDAY(A7,1),"الأحد","الاثنين","الثلاثاء","الأربعاء","الخميس","الجمعة","السبت")) | E7: =IF(OR(M7=0,K7="",L7=""),"",MOD(L7-K7,1)) | F7: =IF(OR(E7="",M7=0),"",IF(ROUND_MODE="للأعلى",CEILING(ROUND((E7*24*AZZ_RATE),3),0.25),ROUND((E7*24*AZZ_RATE)*4,0)/4)) | K7: =IF(OR(M7=0,C7=""),"",IF(ISNUMBER(C7),MOD(C7,1),IFERROR(INDEX(القوائم!$B$1:$B$96,MATCH(TRIM(C7),القوائم!$A$1:$A$96,0)),IFERROR(MOD(TIMEVALUE(C7),1),"")))) | L7: =IF(OR(M7=0,D7=""),"",IF(ISNUMBER(D7),MOD(D7,1),IFERROR(INDEX(القوائم!$B$1:$B$96,MATCH(TRIM(D7),القوائم!$A$1:$A$96,0)),IFERROR(MOD(TIMEVALUE(D7),1),"")))) | M7: =IF(A7="",0,IF(AND(A7>=MSTART,A7<=MEND),1,0)) -> 0
A8: =IF(AND(1<=NW,WFIRST+1>=MSTART,WFIRST+1<=MEND),WFIRST+1,"") | B8: =IF(A8="","",CHOOSE(WEEKDAY(A8,1),"الأحد","الاثنين","الثلاثاء","الأربعاء","الخميس","الجمعة","السبت")) | E8: =IF(OR(M8=0,K8="",L8=""),"",MOD(L8-K8,1)) | F8: =IF(OR(E8="",M8=0),"",IF(ROUND_MODE="للأعلى",CEILING(ROUND((E8*24*AZZ_RATE),3),0.25),ROUND((E8*24*AZZ_RATE)*4,0)/4)) | K8: =IF(OR(M8=0,C8=""),"",IF(ISNUMBER(C8),MOD(C8,1),IFERROR(INDEX(القوائم!$B$1:$B$96,MATCH(TRIM(C8),القوائم!$A$1:$A$96,0)),IFERROR(MOD(TIMEVALUE(C8),1),"")))) | L8: =IF(OR(M8=0,D8=""),"",IF(ISNUMBER(D8),MOD(D8,1),IFERROR(INDEX(القوائم!$B$1:$B$96,MATCH(TRIM(D8),القوائم!$A$1:$A$96,0)),IFERROR(MOD(TIMEVALUE(D8),1),"")))) | M8: =IF(A8="",0,IF(AND(A8>=MSTART,A8<=MEND),1,0)) -> 0
A9: =IF(AND(1<=NW,WFIRST+2>=MSTART,WFIRST+2<=MEND),WFIRST+2,"") | B9: =IF(A9="","",CHOOSE(WEEKDAY(A9,1),"الأحد","الاثنين","الثلاثاء","الأربعاء","الخميس","الجمعة","السبت")) | E9: =IF(OR(M9=0,K9="",L9=""),"",MOD(L9-K9,1)) | F9: =IF(OR(E9="",M9=0),"",IF(ROUND_MODE="للأعلى",CEILING(ROUND((E9*24*AZZ_RATE),3),0.25),ROUND((E9*24*AZZ_RATE)*4,0)/4)) | K9: =IF(OR(M9=0,C9=""),"",IF(ISNUMBER(C9),MOD(C9,1),IFERROR(INDEX(القوائم!$B$1:$B$96,MATCH(TRIM(C9),القوائم!$A$1:$A$96,0)),IFERROR(MOD(TIMEVALUE(C9),1),"")))) | L9: =IF(OR(M9=0,D9=""),"",IF(ISNUMBER(D9),MOD(D9,1),IFERROR(INDEX(القوائم!$B$1:$B$96,MATCH(TRIM(D9),القوائم!$A$1:$A$96,0)),IFERROR(MOD(TIMEVALUE(D9),1),"")))) | M9: =IF(A9="",0,IF(AND(A9>=MSTART,A9<=MEND),1,0)) -> 0
A10: =IF(AND(1<=NW,WFIRST+3>=MSTART,WFIRST+3<=MEND),WFIRST+3,"") | B10: =IF(A10="","",CHOOSE(WEEKDAY(A10,1),"الأحد","الاثنين","الثلاثاء","الأربعاء","الخميس","الجمعة","السبت")) | E10: =IF(OR(M10=0,K10="",L10=""),"",MOD(L10-K10,1)) | F10: =IF(OR(E10="",M10=0),"",IF(ROUND_MODE="للأعلى",CEILING(ROUND((E10*24*AZZ_RATE),3),0.25),ROUND((E10*24*AZZ_RATE)*4,0)/4)) | K10: =IF(OR(M10=0,C10=""),"",IF(ISNUMBER(C10),MOD(C10,1),IFERROR(INDEX(القوائم!$B$1:$B$96,MATCH(TRIM(C10),القوائم!$A$1:$A$96,0)),IFERROR(MOD(TIMEVALUE(C10),1),"")))) | L10: =IF(OR(M10=0,D10=""),"",IF(ISNUMBER(D10),MOD(D10,1),IFERROR(INDEX(القوائم!$B$1:$B$96,MATCH(TRIM(D10),القوائم!$A$1:$A$96,0)),IFERROR(MOD(TIMEVALUE(D10),1),"")))) | M10: =IF(A10="",0,IF(AND(A10>=MSTART,A10<=MEND),1,0)) -> 0
A11: =IF(AND(1<=NW,WFIRST+4>=MSTART,WFIRST+4<=MEND),WFIRST+4,"") | B11: =IF(A11="","",CHOOSE(WEEKDAY(A11,1),"الأحد","الاثنين","الثلاثاء","الأربعاء","الخميس","الجمعة","السبت")) | E11: =IF(OR(M11=0,K11="",L11=""),"",MOD(L11-K11,1)) | F11: =IF(OR(E11="",M11=0),"",IF(ROUND_MODE="للأعلى",CEILING(ROUND((E11*24*AZZ_RATE),3),0.25),ROUND((E11*24*AZZ_RATE)*4,0)/4)) | K11: =IF(OR(M11=0,C11=""),"",IF(ISNUMBER(C11),MOD(C11,1),IFERROR(INDEX(القوائم!$B$1:$B$96,MATCH(TRIM(C11),القوائم!$A$1:$A$96,0)),IFERROR(MOD(TIMEVALUE(C11),1),"")))) | L11: =IF(OR(M11=0,D11=""),"",IF(ISNUMBER(D11),MOD(D11,1),IFERROR(INDEX(القوائم!$B$1:$B$96,MATCH(TRIM(D11),القوائم!$A$1:$A$96,0)),IFERROR(MOD(TIMEVALUE(D11),1),"")))) | M11: =IF(A11="",0,IF(AND(A11>=MSTART,A11<=MEND),1,0)) -> 0
A12: =IF(AND(1<=NW,WFIRST+5>=MSTART,WFIRST+5<=MEND),WFIRST+5,"") -> 46296 | B12: =IF(A12="","",CHOOSE(WEEKDAY(A12,1),"الأحد","الاثنين","الثلاثاء","الأربعاء","الخميس","الجمعة","السبت")) -> الخميس | E12: =IF(OR(M12=0,K12="",L12=""),"",MOD(L12-K12,1)) | F12: =IF(OR(E12="",M12=0),"",IF(ROUND_MODE="للأعلى",CEILING(ROUND((E12*24*AZZ_RATE),3),0.25),ROUND((E12*24*AZZ_RATE)*4,0)/4)) | K12: =IF(OR(M12=0,C12=""),"",IF(ISNUMBER(C12),MOD(C12,1),IFERROR(INDEX(القوائم!$B$1:$B$96,MATCH(TRIM(C12),القوائم!$A$1:$A$96,0)),IFERROR(MOD(TIMEVALUE(C12),1),"")))) | L12: =IF(OR(M12=0,D12=""),"",IF(ISNUMBER(D12),MOD(D12,1),IFERROR(INDEX(القوائم!$B$1:$B$96,MATCH(TRIM(D12),القوائم!$A$1:$A$96,0)),IFERROR(MOD(TIMEVALUE(D12),1),"")))) | M12: =IF(A12="",0,IF(AND(A12>=MSTART,A12<=MEND),1,0)) -> 1
A13: =IF(AND(1<=NW,WFIRST+6>=MSTART,WFIRST+6<=MEND),WFIRST+6,"") -> 46297 | B13: =IF(A13="","",CHOOSE(WEEKDAY(A13,1),"الأحد","الاثنين","الثلاثاء","الأربعاء","الخميس","الجمعة","السبت")) -> الجمعة | E13: =IF(OR(M13=0,K13="",L13=""),"",MOD(L13-K13,1)) | F13: =IF(OR(E13="",M13=0),"",IF(ROUND_MODE="للأعلى",CEILING(ROUND((E13*24*AZZ_RATE),3),0.25),ROUND((E13*24*AZZ_RATE)*4,0)/4)) | K13: =IF(OR(M13=0,C13=""),"",IF(ISNUMBER(C13),MOD(C13,1),IFERROR(INDEX(القوائم!$B$1:$B$96,MATCH(TRIM(C13),القوائم!$A$1:$A$96,0)),IFERROR(MOD(TIMEVALUE(C13),1),"")))) | L13: =IF(OR(M13=0,D13=""),"",IF(ISNUMBER(D13),MOD(D13,1),IFERROR(INDEX(القوائم!$B$1:$B$96,MATCH(TRIM(D13),القوائم!$A$1:$A$96,0)),IFERROR(MOD(TIMEVALUE(D13),1),"")))) | M13: =IF(A13="",0,IF(AND(A13>=MSTART,A13<=MEND),1,0)) -> 1
A14: =IF(1<=NW,"مجموع أيام الأسبوع الأول","") -> مجموع أيام الأسبوع الأول | E14: =IF(1<=NW,SUM(E7:E13),"") -> 0 | F14: =IF(1<=NW,SUM(F7:F13),"") -> 0 | H14: =IF(1<=NW,SUM(H7:H13),"") -> 0
A15: =IF(1<=NW,"ساعات تحميل الجبسمبورد بهالأسبوع (رقم: 2 أو 1.5) ←","") -> ساعات تحميل الجبسمبورد بهالأسبوع (رقم: 2 أو 1.5) ← | F15: =IF(1<=NW,N(F14)+IF(ROUND_MODE="للأعلى",CEILING(ROUND((N(E15)*(GYP_RATE-AZZ_RATE)),3),0.25),ROUND((N(E15)*(GYP_RATE-AZZ_RATE))*4,0)/4),"") -> 0 | G15: =IF(1<=NW,"← المستحق النهائي للأسبوع (دينار) مع فرق الجبسمبورد","") -> ← المستحق النهائي للأسبوع (دينار) مع فرق الجبسمبورد
A16: =IF(2<=NW,"الأسبوع الثاني","") -> الأسبوع الثاني
A17: =IF(AND(2<=NW,WFIRST+7>=MSTART,WFIRST+7<=MEND),WFIRST+7,"") -> 46298 | B17: =IF(A17="","",CHOOSE(WEEKDAY(A17,1),"الأحد","الاثنين","الثلاثاء","الأربعاء","الخميس","الجمعة","السبت")) -> السبت | E17: =IF(OR(M17=0,K17="",L17=""),"",MOD(L17-K17,1)) | F17: =IF(OR(E17="",M17=0),"",IF(ROUND_MODE="للأعلى",CEILING(ROUND((E17*24*AZZ_RATE),3),0.25),ROUND((E17*24*AZZ_RATE)*4,0)/4)) | K17: =IF(OR(M17=0,C17=""),"",IF(ISNUMBER(C17),MOD(C17,1),IFERROR(INDEX(القوائم!$B$1:$B$96,MATCH(TRIM(C17),القوائم!$A$1:$A$96,0)),IFERROR(MOD(TIMEVALUE(C17),1),"")))) | L17: =IF(OR(M17=0,D17=""),"",IF(ISNUMBER(D17),MOD(D17,1),IFERROR(INDEX(القوائم!$B$1:$B$96,MATCH(TRIM(D17),القوائم!$A$1:$A$96,0)),IFERROR(MOD(TIMEVALUE(D17),1),"")))) | M17: =IF(A17="",0,IF(AND(A17>=MSTART,A17<=MEND),1,0)) -> 1
A18: =IF(AND(2<=NW,WFIRST+8>=MSTART,WFIRST+8<=MEND),WFIRST+8,"") -> 46299 | B18: =IF(A18="","",CHOOSE(WEEKDAY(A18,1),"الأحد","الاثنين","الثلاثاء","الأربعاء","الخميس","الجمعة","السبت")) -> الأحد | E18: =IF(OR(M18=0,K18="",L18=""),"",MOD(L18-K18,1)) | F18: =IF(OR(E18="",M18=0),"",IF(ROUND_MODE="للأعلى",CEILING(ROUND((E18*24*AZZ_RATE),3),0.25),ROUND((E18*24*AZZ_RATE)*4,0)/4)) | K18: =IF(OR(M18=0,C18=""),"",IF(ISNUMBER(C18),MOD(C18,1),IFERROR(INDEX(القوائم!$B$1:$B$96,MATCH(TRIM(C18),القوائم!$A$1:$A$96,0)),IFERROR(MOD(TIMEVALUE(C18),1),"")))) | L18: =IF(OR(M18=0,D18=""),"",IF(ISNUMBER(D18),MOD(D18,1),IFERROR(INDEX(القوائم!$B$1:$B$96,MATCH(TRIM(D18),القوائم!$A$1:$A$96,0)),IFERROR(MOD(TIMEVALUE(D18),1),"")))) | M18: =IF(A18="",0,IF(AND(A18>=MSTART,A18<=MEND),1,0)) -> 1
A19: =IF(AND(2<=NW,WFIRST+9>=MSTART,WFIRST+9<=MEND),WFIRST+9,"") -> 46300 | B19: =IF(A19="","",CHOOSE(WEEKDAY(A19,1),"الأحد","الاثنين","الثلاثاء","الأربعاء","الخميس","الجمعة","السبت")) -> الاثنين | E19: =IF(OR(M19=0,K19="",L19=""),"",MOD(L19-K19,1)) | F19: =IF(OR(E19="",M19=0),"",IF(ROUND_MODE="للأعلى",CEILING(ROUND((E19*24*AZZ_RATE),3),0.25),ROUND((E19*24*AZZ_RATE)*4,0)/4)) | K19: =IF(OR(M19=0,C19=""),"",IF(ISNUMBER(C19),MOD(C19,1),IFERROR(INDEX(القوائم!$B$1:$B$96,MATCH(TRIM(C19),القوائم!$A$1:$A$96,0)),IFERROR(MOD(TIMEVALUE(C19),1),"")))) | L19: =IF(OR(M19=0,D19=""),"",IF(ISNUMBER(D19),MOD(D19,1),IFERROR(INDEX(القوائم!$B$1:$B$96,MATCH(TRIM(D19),القوائم!$A$1:$A$96,0)),IFERROR(MOD(TIMEVALUE(D19),1),"")))) | M19: =IF(A19="",0,IF(AND(A19>=MSTART,A19<=MEND),1,0)) -> 1
A20: =IF(AND(2<=NW,WFIRST+10>=MSTART,WFIRST+10<=MEND),WFIRST+10,"") -> 46301 | B20: =IF(A20="","",CHOOSE(WEEKDAY(A20,1),"الأحد","الاثنين","الثلاثاء","الأربعاء","الخميس","الجمعة","السبت")) -> الثلاثاء | E20: =IF(OR(M20=0,K20="",L20=""),"",MOD(L20-K20,1)) | F20: =IF(OR(E20="",M20=0),"",IF(ROUND_MODE="للأعلى",CEILING(ROUND((E20*24*AZZ_RATE),3),0.25),ROUND((E20*24*AZZ_RATE)*4,0)/4)) | K20: =IF(OR(M20=0,C20=""),"",IF(ISNUMBER(C20),MOD(C20,1),IFERROR(INDEX(القوائم!$B$1:$B$96,MATCH(TRIM(C20),القوائم!$A$1:$A$96,0)),IFERROR(MOD(TIMEVALUE(C20),1),"")))) | L20: =IF(OR(M20=0,D20=""),"",IF(ISNUMBER(D20),MOD(D20,1),IFERROR(INDEX(القوائم!$B$1:$B$96,MATCH(TRIM(D20),القوائم!$A$1:$A$96,0)),IFERROR(MOD(TIMEVALUE(D20),1),"")))) | M20: =IF(A20="",0,IF(AND(A20>=MSTART,A20<=MEND),1,0)) -> 1
A21: =IF(AND(2<=NW,WFIRST+11>=MSTART,WFIRST+11<=MEND),WFIRST+11,"") -> 46302 | B21: =IF(A21="","",CHOOSE(WEEKDAY(A21,1),"الأحد","الاثنين","الثلاثاء","الأربعاء","الخميس","الجمعة","السبت")) -> الأربعاء | E21: =IF(OR(M21=0,K21="",L21=""),"",MOD(L21-K21,1)) | F21: =IF(OR(E21="",M21=0),"",IF(ROUND_MODE="للأعلى",CEILING(ROUND((E21*24*AZZ_RATE),3),0.25),ROUND((E21*24*AZZ_RATE)*4,0)/4)) | K21: =IF(OR(M21=0,C21=""),"",IF(ISNUMBER(C21),MOD(C21,1),IFERROR(INDEX(القوائم!$B$1:$B$96,MATCH(TRIM(C21),القوائم!$A$1:$A$96,0)),IFERROR(MOD(TIMEVALUE(C21),1),"")))) | L21: =IF(OR(M21=0,D21=""),"",IF(ISNUMBER(D21),MOD(D21,1),IFERROR(INDEX(القوائم!$B$1:$B$96,MATCH(TRIM(D21),القوائم!$A$1:$A$96,0)),IFERROR(MOD(TIMEVALUE(D21),1),"")))) | M21: =IF(A21="",0,IF(AND(A21>=MSTART,A21<=MEND),1,0)) -> 1
A22: =IF(AND(2<=NW,WFIRST+12>=MSTART,WFIRST+12<=MEND),WFIRST+12,"") -> 46303 | B22: =IF(A22="","",CHOOSE(WEEKDAY(A22,1),"الأحد","الاثنين","الثلاثاء","الأربعاء","الخميس","الجمعة","السبت")) -> الخميس | E22: =IF(OR(M22=0,K22="",L22=""),"",MOD(L22-K22,1)) | F22: =IF(OR(E22="",M22=0),"",IF(ROUND_MODE="للأعلى",CEILING(ROUND((E22*24*AZZ_RATE),3),0.25),ROUND((E22*24*AZZ_RATE)*4,0)/4)) | K22: =IF(OR(M22=0,C22=""),"",IF(ISNUMBER(C22),MOD(C22,1),IFERROR(INDEX(القوائم!$B$1:$B$96,MATCH(TRIM(C22),القوائم!$A$1:$A$96,0)),IFERROR(MOD(TIMEVALUE(C22),1),"")))) | L22: =IF(OR(M22=0,D22=""),"",IF(ISNUMBER(D22),MOD(D22,1),IFERROR(INDEX(القوائم!$B$1:$B$96,MATCH(TRIM(D22),القوائم!$A$1:$A$96,0)),IFERROR(MOD(TIMEVALUE(D22),1),"")))) | M22: =IF(A22="",0,IF(AND(A22>=MSTART,A22<=MEND),1,0)) -> 1
A23: =IF(AND(2<=NW,WFIRST+13>=MSTART,WFIRST+13<=MEND),WFIRST+13,"") -> 46304 | B23: =IF(A23="","",CHOOSE(WEEKDAY(A23,1),"الأحد","الاثنين","الثلاثاء","الأربعاء","الخميس","الجمعة","السبت")) -> الجمعة | E23: =IF(OR(M23=0,K23="",L23=""),"",MOD(L23-K23,1)) | F23: =IF(OR(E23="",M23=0),"",IF(ROUND_MODE="للأعلى",CEILING(ROUND((E23*24*AZZ_RATE),3),0.25),ROUND((E23*24*AZZ_RATE)*4,0)/4)) | K23: =IF(OR(M23=0,C23=""),"",IF(ISNUMBER(C23),MOD(C23,1),IFERROR(INDEX(القوائم!$B$1:$B$96,MATCH(TRIM(C23),القوائم!$A$1:$A$96,0)),IFERROR(MOD(TIMEVALUE(C23),1),"")))) | L23: =IF(OR(M23=0,D23=""),"",IF(ISNUMBER(D23),MOD(D23,1),IFERROR(INDEX(القوائم!$B$1:$B$96,MATCH(TRIM(D23),القوائم!$A$1:$A$96,0)),IFERROR(MOD(TIMEVALUE(D23),1),"")))) | M23: =IF(A23="",0,IF(AND(A23>=MSTART,A23<=MEND),1,0)) -> 1
A24: =IF(2<=NW,"مجموع أيام الأسبوع الثاني","") -> مجموع أيام الأسبوع الثاني | E24: =IF(2<=NW,SUM(E17:E23),"") -> 0 | F24: =IF(2<=NW,SUM(F17:F23),"") -> 0 | H24: =IF(2<=NW,SUM(H17:H23),"") -> 0
A25: =IF(2<=NW,"ساعات تحميل الجبسمبورد بهالأسبوع (رقم: 2 أو 1.5) ←","") -> ساعات تحميل الجبسمبورد بهالأسبوع (رقم: 2 أو 1.5) ← | F25: =IF(2<=NW,N(F24)+IF(ROUND_MODE="للأعلى",CEILING(ROUND((N(E25)*(GYP_RATE-AZZ_RATE)),3),0.25),ROUND((N(E25)*(GYP_RATE-AZZ_RATE))*4,0)/4),"") -> 0 | G25: =IF(2<=NW,"← المستحق النهائي للأسبوع (دينار) مع فرق الجبسمبورد","") -> ← المستحق النهائي للأسبوع (دينار) مع فرق الجبسمبورد
A26: =IF(3<=NW,"الأسبوع الثالث","") -> الأسبوع الثالث
A27: =IF(AND(3<=NW,WFIRST+14>=MSTART,WFIRST+14<=MEND),WFIRST+14,"") -> 46305 | B27: =IF(A27="","",CHOOSE(WEEKDAY(A27,1),"الأحد","الاثنين","الثلاثاء","الأربعاء","الخميس","الجمعة","السبت")) -> السبت | E27: =IF(OR(M27=0,K27="",L27=""),"",MOD(L27-K27,1)) | F27: =IF(OR(E27="",M27=0),"",IF(ROUND_MODE="للأعلى",CEILING(ROUND((E27*24*AZZ_RATE),3),0.25),ROUND((E27*24*AZZ_RATE)*4,0)/4)) | K27: =IF(OR(M27=0,C27=""),"",IF(ISNUMBER(C27),MOD(C27,1),IFERROR(INDEX(القوائم!$B$1:$B$96,MATCH(TRIM(C27),القوائم!$A$1:$A$96,0)),IFERROR(MOD(TIMEVALUE(C27),1),"")))) | L27: =IF(OR(M27=0,D27=""),"",IF(ISNUMBER(D27),MOD(D27,1),IFERROR(INDEX(القوائم!$B$1:$B$96,MATCH(TRIM(D27),القوائم!$A$1:$A$96,0)),IFERROR(MOD(TIMEVALUE(D27),1),"")))) | M27: =IF(A27="",0,IF(AND(A27>=MSTART,A27<=MEND),1,0)) -> 1
A28: =IF(AND(3<=NW,WFIRST+15>=MSTART,WFIRST+15<=MEND),WFIRST+15,"") -> 46306 | B28: =IF(A28="","",CHOOSE(WEEKDAY(A28,1),"الأحد","الاثنين","الثلاثاء","الأربعاء","الخميس","الجمعة","السبت")) -> الأحد | E28: =IF(OR(M28=0,K28="",L28=""),"",MOD(L28-K28,1)) | F28: =IF(OR(E28="",M28=0),"",IF(ROUND_MODE="للأعلى",CEILING(ROUND((E28*24*AZZ_RATE),3),0.25),ROUND((E28*24*AZZ_RATE)*4,0)/4)) | K28: =IF(OR(M28=0,C28=""),"",IF(ISNUMBER(C28),MOD(C28,1),IFERROR(INDEX(القوائم!$B$1:$B$96,MATCH(TRIM(C28),القوائم!$A$1:$A$96,0)),IFERROR(MOD(TIMEVALUE(C28),1),"")))) | L28: =IF(OR(M28=0,D28=""),"",IF(ISNUMBER(D28),MOD(D28,1),IFERROR(INDEX(القوائم!$B$1:$B$96,MATCH(TRIM(D28),القوائم!$A$1:$A$96,0)),IFERROR(MOD(TIMEVALUE(D28),1),"")))) | M28: =IF(A28="",0,IF(AND(A28>=MSTART,A28<=MEND),1,0)) -> 1
A29: =IF(AND(3<=NW,WFIRST+16>=MSTART,WFIRST+16<=MEND),WFIRST+16,"") -> 46307 | B29: =IF(A29="","",CHOOSE(WEEKDAY(A29,1),"الأحد","الاثنين","الثلاثاء","الأربعاء","الخميس","الجمعة","السبت")) -> الاثنين | E29: =IF(OR(M29=0,K29="",L29=""),"",MOD(L29-K29,1)) | F29: =IF(OR(E29="",M29=0),"",IF(ROUND_MODE="للأعلى",CEILING(ROUND((E29*24*AZZ_RATE),3),0.25),ROUND((E29*24*AZZ_RATE)*4,0)/4)) | K29: =IF(OR(M29=0,C29=""),"",IF(ISNUMBER(C29),MOD(C29,1),IFERROR(INDEX(القوائم!$B$1:$B$96,MATCH(TRIM(C29),القوائم!$A$1:$A$96,0)),IFERROR(MOD(TIMEVALUE(C29),1),"")))) | L29: =IF(OR(M29=0,D29=""),"",IF(ISNUMBER(D29),MOD(D29,1),IFERROR(INDEX(القوائم!$B$1:$B$96,MATCH(TRIM(D29),القوائم!$A$1:$A$96,0)),IFERROR(MOD(TIMEVALUE(D29),1),"")))) | M29: =IF(A29="",0,IF(AND(A29>=MSTART,A29<=MEND),1,0)) -> 1
A30: =IF(AND(3<=NW,WFIRST+17>=MSTART,WFIRST+17<=MEND),WFIRST+17,"") -> 46308 | B30: =IF(A30="","",CHOOSE(WEEKDAY(A30,1),"الأحد","الاثنين","الثلاثاء","الأربعاء","الخميس","الجمعة","السبت")) -> الثلاثاء | E30: =IF(OR(M30=0,K30="",L30=""),"",MOD(L30-K30,1)) | F30: =IF(OR(E30="",M30=0),"",IF(ROUND_MODE="للأعلى",CEILING(ROUND((E30*24*AZZ_RATE),3),0.25),ROUND((E30*24*AZZ_RATE)*4,0)/4)) | K30: =IF(OR(M30=0,C30=""),"",IF(ISNUMBER(C30),MOD(C30,1),IFERROR(INDEX(القوائم!$B$1:$B$96,MATCH(TRIM(C30),القوائم!$A$1:$A$96,0)),IFERROR(MOD(TIMEVALUE(C30),1),"")))) | L30: =IF(OR(M30=0,D30=""),"",IF(ISNUMBER(D30),MOD(D30,1),IFERROR(INDEX(القوائم!$B$1:$B$96,MATCH(TRIM(D30),القوائم!$A$1:$A$96,0)),IFERROR(MOD(TIMEVALUE(D30),1),"")))) | M30: =IF(A30="",0,IF(AND(A30>=MSTART,A30<=MEND),1,0)) -> 1
A31: =IF(AND(3<=NW,WFIRST+18>=MSTART,WFIRST+18<=MEND),WFIRST+18,"") -> 46309 | B31: =IF(A31="","",CHOOSE(WEEKDAY(A31,1),"الأحد","الاثنين","الثلاثاء","الأربعاء","الخميس","الجمعة","السبت")) -> الأربعاء | E31: =IF(OR(M31=0,K31="",L31=""),"",MOD(L31-K31,1)) | F31: =IF(OR(E31="",M31=0),"",IF(ROUND_MODE="للأعلى",CEILING(ROUND((E31*24*AZZ_RATE),3),0.25),ROUND((E31*24*AZZ_RATE)*4,0)/4)) | K31: =IF(OR(M31=0,C31=""),"",IF(ISNUMBER(C31),MOD(C31,1),IFERROR(INDEX(القوائم!$B$1:$B$96,MATCH(TRIM(C31),القوائم!$A$1:$A$96,0)),IFERROR(MOD(TIMEVALUE(C31),1),"")))) | L31: =IF(OR(M31=0,D31=""),"",IF(ISNUMBER(D31),MOD(D31,1),IFERROR(INDEX(القوائم!$B$1:$B$96,MATCH(TRIM(D31),القوائم!$A$1:$A$96,0)),IFERROR(MOD(TIMEVALUE(D31),1),"")))) | M31: =IF(A31="",0,IF(AND(A31>=MSTART,A31<=MEND),1,0)) -> 1
A32: =IF(AND(3<=NW,WFIRST+19>=MSTART,WFIRST+19<=MEND),WFIRST+19,"") -> 46310 | B32: =IF(A32="","",CHOOSE(WEEKDAY(A32,1),"الأحد","الاثنين","الثلاثاء","الأربعاء","الخميس","الجمعة","السبت")) -> الخميس | E32: =IF(OR(M32=0,K32="",L32=""),"",MOD(L32-K32,1)) | F32: =IF(OR(E32="",M32=0),"",IF(ROUND_MODE="للأعلى",CEILING(ROUND((E32*24*AZZ_RATE),3),0.25),ROUND((E32*24*AZZ_RATE)*4,0)/4)) | K32: =IF(OR(M32=0,C32=""),"",IF(ISNUMBER(C32),MOD(C32,1),IFERROR(INDEX(القوائم!$B$1:$B$96,MATCH(TRIM(C32),القوائم!$A$1:$A$96,0)),IFERROR(MOD(TIMEVALUE(C32),1),"")))) | L32: =IF(OR(M32=0,D32=""),"",IF(ISNUMBER(D32),MOD(D32,1),IFERROR(INDEX(القوائم!$B$1:$B$96,MATCH(TRIM(D32),القوائم!$A$1:$A$96,0)),IFERROR(MOD(TIMEVALUE(D32),1),"")))) | M32: =IF(A32="",0,IF(AND(A32>=MSTART,A32<=MEND),1,0)) -> 1
